2023-07-14 19:28:53,328:ERROR:Error while writing to the Wikibase instance
Traceback (most recent call last):
  File "/home/lubianat/Documents/base_venv/lib/python3.9/site-packages/wikibaseintegrator/entities/baseentity.py", line 244, in _write
    json_result: dict = edit_entity(data=data, id=entity_id, type=self.type, summary=summary, clear=clear, is_bot=is_bot, allow_anonymous=allow_anonymous,
  File "/home/lubianat/Documents/base_venv/lib/python3.9/site-packages/wikibaseintegrator/wbi_helpers.py", line 335, in edit_entity
    return mediawiki_api_call_helper(data=params, is_bot=is_bot, **kwargs)
  File "/home/lubianat/Documents/base_venv/lib/python3.9/site-packages/wikibaseintegrator/wbi_helpers.py", line 217, in mediawiki_api_call_helper
    return mediawiki_api_call('POST', mediawiki_api_url=mediawiki_api_url, session=session, data=data, headers=headers, max_retries=max_retries, retry_after=retry_after, **kwargs)
  File "/home/lubianat/Documents/base_venv/lib/python3.9/site-packages/wikibaseintegrator/wbi_helpers.py", line 127, in mediawiki_api_call
    raise ModificationFailed(json_data['error'])
wikibaseintegrator.wbi_exceptions.ModificationFailed: '[[Item:Q349|Q349]] not found'
2023-07-14 19:28:53,333:ERROR:Failed to write item: '[[Item:Q349|Q349]] not found'
2023-07-14 19:29:24,628:ERROR:Error while writing to the Wikibase instance
Traceback (most recent call last):
  File "/home/lubianat/Documents/base_venv/lib/python3.9/site-packages/wikibaseintegrator/entities/baseentity.py", line 244, in _write
    json_result: dict = edit_entity(data=data, id=entity_id, type=self.type, summary=summary, clear=clear, is_bot=is_bot, allow_anonymous=allow_anonymous,
  File "/home/lubianat/Documents/base_venv/lib/python3.9/site-packages/wikibaseintegrator/wbi_helpers.py", line 335, in edit_entity
    return mediawiki_api_call_helper(data=params, is_bot=is_bot, **kwargs)
  File "/home/lubianat/Documents/base_venv/lib/python3.9/site-packages/wikibaseintegrator/wbi_helpers.py", line 217, in mediawiki_api_call_helper
    return mediawiki_api_call('POST', mediawiki_api_url=mediawiki_api_url, session=session, data=data, headers=headers, max_retries=max_retries, retry_after=retry_after, **kwargs)
  File "/home/lubianat/Documents/base_venv/lib/python3.9/site-packages/wikibaseintegrator/wbi_helpers.py", line 127, in mediawiki_api_call
    raise ModificationFailed(json_data['error'])
wikibaseintegrator.wbi_exceptions.ModificationFailed: '[[Item:Q349|Q349]] not found'
2023-07-14 19:29:24,628:ERROR:Failed to write item: '[[Item:Q349|Q349]] not found'
2023-07-14 19:37:42,112:ERROR:MissingEntityException encountered: The MW API returned that the entity was missing.
2023-07-14 19:42:23,280:ERROR:MissingEntityException encountered: The MW API returned that the entity was missing.
2023-07-14 19:42:36,575:ERROR:KeyError encountered: '0xd895eec6767970660a846423a409e83454e9ea95'
2023-07-14 19:42:45,283:ERROR:MissingEntityException encountered: The MW API returned that the entity was missing.
2023-07-14 19:55:43,340:ERROR:Error while writing to the Wikibase instance
Traceback (most recent call last):
  File "/home/lubianat/Documents/base_venv/lib/python3.9/site-packages/wikibaseintegrator/entities/baseentity.py", line 244, in _write
    json_result: dict = edit_entity(data=data, id=entity_id, type=self.type, summary=summary, clear=clear, is_bot=is_bot, allow_anonymous=allow_anonymous,
  File "/home/lubianat/Documents/base_venv/lib/python3.9/site-packages/wikibaseintegrator/wbi_helpers.py", line 335, in edit_entity
    return mediawiki_api_call_helper(data=params, is_bot=is_bot, **kwargs)
  File "/home/lubianat/Documents/base_venv/lib/python3.9/site-packages/wikibaseintegrator/wbi_helpers.py", line 217, in mediawiki_api_call_helper
    return mediawiki_api_call('POST', mediawiki_api_url=mediawiki_api_url, session=session, data=data, headers=headers, max_retries=max_retries, retry_after=retry_after, **kwargs)
  File "/home/lubianat/Documents/base_venv/lib/python3.9/site-packages/wikibaseintegrator/wbi_helpers.py", line 127, in mediawiki_api_call
    raise ModificationFailed(json_data['error'])
wikibaseintegrator.wbi_exceptions.ModificationFailed: '[[Item:Q349|Q349]] not found'
2023-07-14 19:55:43,341:ERROR:ModificationFailed error encountered: '[[Item:Q349|Q349]] not found'
2023-07-14 19:55:48,721:ERROR:Error while writing to the Wikibase instance
Traceback (most recent call last):
  File "/home/lubianat/Documents/base_venv/lib/python3.9/site-packages/wikibaseintegrator/entities/baseentity.py", line 244, in _write
    json_result: dict = edit_entity(data=data, id=entity_id, type=self.type, summary=summary, clear=clear, is_bot=is_bot, allow_anonymous=allow_anonymous,
  File "/home/lubianat/Documents/base_venv/lib/python3.9/site-packages/wikibaseintegrator/wbi_helpers.py", line 335, in edit_entity
    return mediawiki_api_call_helper(data=params, is_bot=is_bot, **kwargs)
  File "/home/lubianat/Documents/base_venv/lib/python3.9/site-packages/wikibaseintegrator/wbi_helpers.py", line 217, in mediawiki_api_call_helper
    return mediawiki_api_call('POST', mediawiki_api_url=mediawiki_api_url, session=session, data=data, headers=headers, max_retries=max_retries, retry_after=retry_after, **kwargs)
  File "/home/lubianat/Documents/base_venv/lib/python3.9/site-packages/wikibaseintegrator/wbi_helpers.py", line 127, in mediawiki_api_call
    raise ModificationFailed(json_data['error'])
wikibaseintegrator.wbi_exceptions.ModificationFailed: '[[Item:Q334|Q334]] not found'
2023-07-14 19:55:48,722:ERROR:ModificationFailed error encountered: '[[Item:Q334|Q334]] not found'
2023-07-14 19:57:31,356:ERROR:KeyError encountered: 'Proposal 307'
2023-07-14 19:57:31,358:ERROR:KeyError encountered: 'Proposal 315'
2023-07-14 19:57:31,359:ERROR:KeyError encountered: 'Proposal 313'
2023-07-14 19:57:31,360:ERROR:KeyError encountered: 'Proposal 316'
2023-07-14 19:57:33,956:ERROR:KeyError encountered: 'Proposal 306'
2023-07-14 19:57:33,956:ERROR:KeyError encountered: 'Proposal 303'
2023-07-14 19:57:42,759:ERROR:KeyError encountered: 'Proposal 305'
2023-07-14 19:57:44,443:ERROR:Error while writing to the Wikibase instance
Traceback (most recent call last):
  File "/home/lubianat/Documents/base_venv/lib/python3.9/site-packages/wikibaseintegrator/entities/baseentity.py", line 244, in _write
    json_result: dict = edit_entity(data=data, id=entity_id, type=self.type, summary=summary, clear=clear, is_bot=is_bot, allow_anonymous=allow_anonymous,
  File "/home/lubianat/Documents/base_venv/lib/python3.9/site-packages/wikibaseintegrator/wbi_helpers.py", line 335, in edit_entity
    return mediawiki_api_call_helper(data=params, is_bot=is_bot, **kwargs)
  File "/home/lubianat/Documents/base_venv/lib/python3.9/site-packages/wikibaseintegrator/wbi_helpers.py", line 217, in mediawiki_api_call_helper
    return mediawiki_api_call('POST', mediawiki_api_url=mediawiki_api_url, session=session, data=data, headers=headers, max_retries=max_retries, retry_after=retry_after, **kwargs)
  File "/home/lubianat/Documents/base_venv/lib/python3.9/site-packages/wikibaseintegrator/wbi_helpers.py", line 127, in mediawiki_api_call
    raise ModificationFailed(json_data['error'])
wikibaseintegrator.wbi_exceptions.ModificationFailed: '[[Item:Q349|Q349]] not found'
2023-07-14 19:57:44,444:ERROR:ModificationFailed error encountered: '[[Item:Q349|Q349]] not found'
2023-07-14 20:03:59,651:ERROR:KeyError encountered: 'Proposal 307'
2023-07-14 20:03:59,654:ERROR:KeyError encountered: 'Proposal 315'
2023-07-14 20:03:59,656:ERROR:KeyError encountered: 'Proposal 313'
2023-07-14 20:03:59,658:ERROR:KeyError encountered: 'Proposal 316'
2023-07-14 20:04:07,633:ERROR:KeyError encountered: 'Proposal 306'
2023-07-14 20:04:07,634:ERROR:KeyError encountered: 'Proposal 303'
2023-07-14 20:04:15,539:ERROR:KeyError encountered: 'Proposal 305'
2023-07-14 20:04:18,175:ERROR:Error while writing to the Wikibase instance
Traceback (most recent call last):
  File "/home/lubianat/Documents/base_venv/lib/python3.9/site-packages/wikibaseintegrator/entities/baseentity.py", line 244, in _write
    json_result: dict = edit_entity(data=data, id=entity_id, type=self.type, summary=summary, clear=clear, is_bot=is_bot, allow_anonymous=allow_anonymous,
  File "/home/lubianat/Documents/base_venv/lib/python3.9/site-packages/wikibaseintegrator/wbi_helpers.py", line 335, in edit_entity
    return mediawiki_api_call_helper(data=params, is_bot=is_bot, **kwargs)
  File "/home/lubianat/Documents/base_venv/lib/python3.9/site-packages/wikibaseintegrator/wbi_helpers.py", line 217, in mediawiki_api_call_helper
    return mediawiki_api_call('POST', mediawiki_api_url=mediawiki_api_url, session=session, data=data, headers=headers, max_retries=max_retries, retry_after=retry_after, **kwargs)
  File "/home/lubianat/Documents/base_venv/lib/python3.9/site-packages/wikibaseintegrator/wbi_helpers.py", line 127, in mediawiki_api_call
    raise ModificationFailed(json_data['error'])
wikibaseintegrator.wbi_exceptions.ModificationFailed: '[[Item:Q349|Q349]] not found'
2023-07-14 20:04:18,176:ERROR:ModificationFailed error encountered: '[[Item:Q349|Q349]] not found'
2023-07-14 20:04:24,252:ERROR:Error while writing to the Wikibase instance
Traceback (most recent call last):
  File "/home/lubianat/Documents/base_venv/lib/python3.9/site-packages/wikibaseintegrator/entities/baseentity.py", line 244, in _write
    json_result: dict = edit_entity(data=data, id=entity_id, type=self.type, summary=summary, clear=clear, is_bot=is_bot, allow_anonymous=allow_anonymous,
  File "/home/lubianat/Documents/base_venv/lib/python3.9/site-packages/wikibaseintegrator/wbi_helpers.py", line 335, in edit_entity
    return mediawiki_api_call_helper(data=params, is_bot=is_bot, **kwargs)
  File "/home/lubianat/Documents/base_venv/lib/python3.9/site-packages/wikibaseintegrator/wbi_helpers.py", line 217, in mediawiki_api_call_helper
    return mediawiki_api_call('POST', mediawiki_api_url=mediawiki_api_url, session=session, data=data, headers=headers, max_retries=max_retries, retry_after=retry_after, **kwargs)
  File "/home/lubianat/Documents/base_venv/lib/python3.9/site-packages/wikibaseintegrator/wbi_helpers.py", line 127, in mediawiki_api_call
    raise ModificationFailed(json_data['error'])
wikibaseintegrator.wbi_exceptions.ModificationFailed: '[[Item:Q334|Q334]] not found'
2023-07-14 20:04:24,252:ERROR:ModificationFailed error encountered: '[[Item:Q334|Q334]] not found'
2023-07-14 20:05:21,305:ERROR:KeyError encountered: 'Proposal 307'
2023-07-14 20:05:21,306:ERROR:KeyError encountered: 'Proposal 315'
2023-07-14 20:05:21,306:ERROR:KeyError encountered: 'Proposal 313'
2023-07-14 20:05:21,306:ERROR:KeyError encountered: 'Proposal 316'
2023-07-14 20:05:26,504:ERROR:KeyError encountered: 'Proposal 306'
2023-07-14 20:05:26,505:ERROR:KeyError encountered: 'Proposal 303'
2023-07-14 20:05:38,663:ERROR:KeyError encountered: 'Proposal 305'
2023-07-14 20:05:41,629:ERROR:Error while writing to the Wikibase instance
Traceback (most recent call last):
  File "/home/lubianat/Documents/base_venv/lib/python3.9/site-packages/wikibaseintegrator/entities/baseentity.py", line 244, in _write
    json_result: dict = edit_entity(data=data, id=entity_id, type=self.type, summary=summary, clear=clear, is_bot=is_bot, allow_anonymous=allow_anonymous,
  File "/home/lubianat/Documents/base_venv/lib/python3.9/site-packages/wikibaseintegrator/wbi_helpers.py", line 335, in edit_entity
    return mediawiki_api_call_helper(data=params, is_bot=is_bot, **kwargs)
  File "/home/lubianat/Documents/base_venv/lib/python3.9/site-packages/wikibaseintegrator/wbi_helpers.py", line 217, in mediawiki_api_call_helper
    return mediawiki_api_call('POST', mediawiki_api_url=mediawiki_api_url, session=session, data=data, headers=headers, max_retries=max_retries, retry_after=retry_after, **kwargs)
  File "/home/lubianat/Documents/base_venv/lib/python3.9/site-packages/wikibaseintegrator/wbi_helpers.py", line 127, in mediawiki_api_call
    raise ModificationFailed(json_data['error'])
wikibaseintegrator.wbi_exceptions.ModificationFailed: '[[Item:Q349|Q349]] not found'
2023-07-14 20:05:41,630:ERROR:ModificationFailed error encountered: '[[Item:Q349|Q349]] not found'
2023-07-14 20:05:49,928:ERROR:Error while writing to the Wikibase instance
Traceback (most recent call last):
  File "/home/lubianat/Documents/base_venv/lib/python3.9/site-packages/wikibaseintegrator/entities/baseentity.py", line 244, in _write
    json_result: dict = edit_entity(data=data, id=entity_id, type=self.type, summary=summary, clear=clear, is_bot=is_bot, allow_anonymous=allow_anonymous,
  File "/home/lubianat/Documents/base_venv/lib/python3.9/site-packages/wikibaseintegrator/wbi_helpers.py", line 335, in edit_entity
    return mediawiki_api_call_helper(data=params, is_bot=is_bot, **kwargs)
  File "/home/lubianat/Documents/base_venv/lib/python3.9/site-packages/wikibaseintegrator/wbi_helpers.py", line 217, in mediawiki_api_call_helper
    return mediawiki_api_call('POST', mediawiki_api_url=mediawiki_api_url, session=session, data=data, headers=headers, max_retries=max_retries, retry_after=retry_after, **kwargs)
  File "/home/lubianat/Documents/base_venv/lib/python3.9/site-packages/wikibaseintegrator/wbi_helpers.py", line 127, in mediawiki_api_call
    raise ModificationFailed(json_data['error'])
wikibaseintegrator.wbi_exceptions.ModificationFailed: '[[Item:Q334|Q334]] not found'
2023-07-14 20:05:49,929:ERROR:ModificationFailed error encountered: '[[Item:Q334|Q334]] not found'
2023-07-14 20:20:05,950:ERROR:KeyError encountered: 'Proposal 307'
2023-07-14 20:20:05,951:ERROR:KeyError encountered: 'Proposal 315'
2023-07-14 20:20:05,952:ERROR:KeyError encountered: 'Proposal 313'
2023-07-14 20:20:05,952:ERROR:KeyError encountered: 'Proposal 316'
2023-07-14 20:20:15,219:ERROR:KeyError encountered: 'Proposal 306'
2023-07-14 20:20:15,219:ERROR:KeyError encountered: 'Proposal 303'
2023-07-14 20:20:35,637:ERROR:KeyError encountered: 'Proposal 305'
2023-07-14 20:20:40,145:ERROR:Error while writing to the Wikibase instance
Traceback (most recent call last):
  File "/home/lubianat/Documents/base_venv/lib/python3.9/site-packages/wikibaseintegrator/entities/baseentity.py", line 244, in _write
    json_result: dict = edit_entity(data=data, id=entity_id, type=self.type, summary=summary, clear=clear, is_bot=is_bot, allow_anonymous=allow_anonymous,
  File "/home/lubianat/Documents/base_venv/lib/python3.9/site-packages/wikibaseintegrator/wbi_helpers.py", line 335, in edit_entity
    return mediawiki_api_call_helper(data=params, is_bot=is_bot, **kwargs)
  File "/home/lubianat/Documents/base_venv/lib/python3.9/site-packages/wikibaseintegrator/wbi_helpers.py", line 217, in mediawiki_api_call_helper
    return mediawiki_api_call('POST', mediawiki_api_url=mediawiki_api_url, session=session, data=data, headers=headers, max_retries=max_retries, retry_after=retry_after, **kwargs)
  File "/home/lubianat/Documents/base_venv/lib/python3.9/site-packages/wikibaseintegrator/wbi_helpers.py", line 127, in mediawiki_api_call
    raise ModificationFailed(json_data['error'])
wikibaseintegrator.wbi_exceptions.ModificationFailed: '[[Item:Q349|Q349]] not found'
2023-07-14 20:20:40,147:ERROR:ModificationFailed error encountered: '[[Item:Q349|Q349]] not found'
2023-07-14 20:20:51,094:ERROR:Error while writing to the Wikibase instance
Traceback (most recent call last):
  File "/home/lubianat/Documents/base_venv/lib/python3.9/site-packages/wikibaseintegrator/entities/baseentity.py", line 244, in _write
    json_result: dict = edit_entity(data=data, id=entity_id, type=self.type, summary=summary, clear=clear, is_bot=is_bot, allow_anonymous=allow_anonymous,
  File "/home/lubianat/Documents/base_venv/lib/python3.9/site-packages/wikibaseintegrator/wbi_helpers.py", line 335, in edit_entity
    return mediawiki_api_call_helper(data=params, is_bot=is_bot, **kwargs)
  File "/home/lubianat/Documents/base_venv/lib/python3.9/site-packages/wikibaseintegrator/wbi_helpers.py", line 217, in mediawiki_api_call_helper
    return mediawiki_api_call('POST', mediawiki_api_url=mediawiki_api_url, session=session, data=data, headers=headers, max_retries=max_retries, retry_after=retry_after, **kwargs)
  File "/home/lubianat/Documents/base_venv/lib/python3.9/site-packages/wikibaseintegrator/wbi_helpers.py", line 127, in mediawiki_api_call
    raise ModificationFailed(json_data['error'])
wikibaseintegrator.wbi_exceptions.ModificationFailed: '[[Item:Q334|Q334]] not found'
2023-07-14 20:20:51,095:ERROR:ModificationFailed error encountered: '[[Item:Q334|Q334]] not found'
2023-07-14 20:21:41,472:ERROR:KeyError encountered: 'Proposal 307'
2023-07-14 20:21:41,473:ERROR:KeyError encountered: 'Proposal 315'
2023-07-14 20:21:41,473:ERROR:KeyError encountered: 'Proposal 313'
2023-07-14 20:21:41,474:ERROR:KeyError encountered: 'Proposal 316'
2023-07-14 20:21:46,644:ERROR:KeyError encountered: 'Proposal 306'
2023-07-14 20:21:46,644:ERROR:KeyError encountered: 'Proposal 303'
2023-07-14 20:21:58,471:ERROR:KeyError encountered: 'Proposal 305'
2023-07-14 20:22:01,541:ERROR:Error while writing to the Wikibase instance
Traceback (most recent call last):
  File "/home/lubianat/Documents/base_venv/lib/python3.9/site-packages/wikibaseintegrator/entities/baseentity.py", line 244, in _write
    json_result: dict = edit_entity(data=data, id=entity_id, type=self.type, summary=summary, clear=clear, is_bot=is_bot, allow_anonymous=allow_anonymous,
  File "/home/lubianat/Documents/base_venv/lib/python3.9/site-packages/wikibaseintegrator/wbi_helpers.py", line 335, in edit_entity
    return mediawiki_api_call_helper(data=params, is_bot=is_bot, **kwargs)
  File "/home/lubianat/Documents/base_venv/lib/python3.9/site-packages/wikibaseintegrator/wbi_helpers.py", line 217, in mediawiki_api_call_helper
    return mediawiki_api_call('POST', mediawiki_api_url=mediawiki_api_url, session=session, data=data, headers=headers, max_retries=max_retries, retry_after=retry_after, **kwargs)
  File "/home/lubianat/Documents/base_venv/lib/python3.9/site-packages/wikibaseintegrator/wbi_helpers.py", line 127, in mediawiki_api_call
    raise ModificationFailed(json_data['error'])
wikibaseintegrator.wbi_exceptions.ModificationFailed: '[[Item:Q349|Q349]] not found'
2023-07-14 20:22:01,542:ERROR:ModificationFailed error encountered: '[[Item:Q349|Q349]] not found'
2023-07-14 20:22:10,142:ERROR:Error while writing to the Wikibase instance
Traceback (most recent call last):
  File "/home/lubianat/Documents/base_venv/lib/python3.9/site-packages/wikibaseintegrator/entities/baseentity.py", line 244, in _write
    json_result: dict = edit_entity(data=data, id=entity_id, type=self.type, summary=summary, clear=clear, is_bot=is_bot, allow_anonymous=allow_anonymous,
  File "/home/lubianat/Documents/base_venv/lib/python3.9/site-packages/wikibaseintegrator/wbi_helpers.py", line 335, in edit_entity
    return mediawiki_api_call_helper(data=params, is_bot=is_bot, **kwargs)
  File "/home/lubianat/Documents/base_venv/lib/python3.9/site-packages/wikibaseintegrator/wbi_helpers.py", line 217, in mediawiki_api_call_helper
    return mediawiki_api_call('POST', mediawiki_api_url=mediawiki_api_url, session=session, data=data, headers=headers, max_retries=max_retries, retry_after=retry_after, **kwargs)
  File "/home/lubianat/Documents/base_venv/lib/python3.9/site-packages/wikibaseintegrator/wbi_helpers.py", line 127, in mediawiki_api_call
    raise ModificationFailed(json_data['error'])
wikibaseintegrator.wbi_exceptions.ModificationFailed: '[[Item:Q334|Q334]] not found'
2023-07-14 20:22:10,143:ERROR:ModificationFailed error encountered: '[[Item:Q334|Q334]] not found'
2023-07-14 20:26:50,823:ERROR:Error while writing to the Wikibase instance
Traceback (most recent call last):
  File "/home/lubianat/Documents/base_venv/lib/python3.9/site-packages/wikibaseintegrator/entities/baseentity.py", line 244, in _write
    json_result: dict = edit_entity(data=data, id=entity_id, type=self.type, summary=summary, clear=clear, is_bot=is_bot, allow_anonymous=allow_anonymous,
  File "/home/lubianat/Documents/base_venv/lib/python3.9/site-packages/wikibaseintegrator/wbi_helpers.py", line 335, in edit_entity
    return mediawiki_api_call_helper(data=params, is_bot=is_bot, **kwargs)
  File "/home/lubianat/Documents/base_venv/lib/python3.9/site-packages/wikibaseintegrator/wbi_helpers.py", line 217, in mediawiki_api_call_helper
    return mediawiki_api_call('POST', mediawiki_api_url=mediawiki_api_url, session=session, data=data, headers=headers, max_retries=max_retries, retry_after=retry_after, **kwargs)
  File "/home/lubianat/Documents/base_venv/lib/python3.9/site-packages/wikibaseintegrator/wbi_helpers.py", line 127, in mediawiki_api_call
    raise ModificationFailed(json_data['error'])
wikibaseintegrator.wbi_exceptions.ModificationFailed: '[[Item:Q349|Q349]] not found'
2023-07-14 20:26:50,824:ERROR:ModificationFailed error encountered: '[[Item:Q349|Q349]] not found'
2023-07-14 20:27:57,868:ERROR:Error while writing to the Wikibase instance
Traceback (most recent call last):
  File "/home/lubianat/Documents/base_venv/lib/python3.9/site-packages/wikibaseintegrator/entities/baseentity.py", line 244, in _write
    json_result: dict = edit_entity(data=data, id=entity_id, type=self.type, summary=summary, clear=clear, is_bot=is_bot, allow_anonymous=allow_anonymous,
  File "/home/lubianat/Documents/base_venv/lib/python3.9/site-packages/wikibaseintegrator/wbi_helpers.py", line 335, in edit_entity
    return mediawiki_api_call_helper(data=params, is_bot=is_bot, **kwargs)
  File "/home/lubianat/Documents/base_venv/lib/python3.9/site-packages/wikibaseintegrator/wbi_helpers.py", line 217, in mediawiki_api_call_helper
    return mediawiki_api_call('POST', mediawiki_api_url=mediawiki_api_url, session=session, data=data, headers=headers, max_retries=max_retries, retry_after=retry_after, **kwargs)
  File "/home/lubianat/Documents/base_venv/lib/python3.9/site-packages/wikibaseintegrator/wbi_helpers.py", line 127, in mediawiki_api_call
    raise ModificationFailed(json_data['error'])
wikibaseintegrator.wbi_exceptions.ModificationFailed: '[[Item:Q348|Q348]] not found'
2023-07-14 20:27:57,869:ERROR:ModificationFailed error encountered: '[[Item:Q348|Q348]] not found'
2023-07-14 20:28:12,841:ERROR:KeyError encountered: 'Proposal 304'
2023-07-14 20:28:12,841:ERROR:KeyError encountered: 'Proposal 308'
2023-07-14 20:28:12,842:ERROR:KeyError encountered: 'Proposal 311'
2023-07-14 20:28:12,842:ERROR:KeyError encountered: 'Proposal 317'
2023-07-14 20:28:12,843:ERROR:KeyError encountered: 'Proposal 318'
2023-07-14 20:28:12,843:ERROR:KeyError encountered: 'Proposal 319'
2023-07-14 20:30:35,260:ERROR:KeyError encountered: 'Proposal 307'
2023-07-14 20:30:37,940:ERROR:KeyError encountered: 'Proposal 315'
2023-07-14 20:30:37,941:ERROR:KeyError encountered: 'Proposal 313'
2023-07-14 20:30:37,941:ERROR:KeyError encountered: 'Proposal 316'
2023-07-14 20:30:38,600:ERROR:KeyError encountered: 'Proposal 315'
2023-07-14 20:30:38,600:ERROR:KeyError encountered: 'Proposal 306'
2023-07-14 20:30:38,601:ERROR:KeyError encountered: 'Proposal 303'
2023-07-14 20:30:40,052:ERROR:KeyError encountered: 'Proposal 316'
2023-07-14 20:30:44,638:ERROR:KeyError encountered: 'Proposal 316'
2023-07-14 20:30:44,639:ERROR:KeyError encountered: 'Proposal 305'
2023-07-14 20:30:44,639:ERROR:KeyError encountered: 'Proposal 307'
2023-07-14 20:30:52,481:ERROR:Error while writing to the Wikibase instance
Traceback (most recent call last):
  File "/home/lubianat/Documents/base_venv/lib/python3.9/site-packages/wikibaseintegrator/entities/baseentity.py", line 244, in _write
    json_result: dict = edit_entity(data=data, id=entity_id, type=self.type, summary=summary, clear=clear, is_bot=is_bot, allow_anonymous=allow_anonymous,
  File "/home/lubianat/Documents/base_venv/lib/python3.9/site-packages/wikibaseintegrator/wbi_helpers.py", line 335, in edit_entity
    return mediawiki_api_call_helper(data=params, is_bot=is_bot, **kwargs)
  File "/home/lubianat/Documents/base_venv/lib/python3.9/site-packages/wikibaseintegrator/wbi_helpers.py", line 217, in mediawiki_api_call_helper
    return mediawiki_api_call('POST', mediawiki_api_url=mediawiki_api_url, session=session, data=data, headers=headers, max_retries=max_retries, retry_after=retry_after, **kwargs)
  File "/home/lubianat/Documents/base_venv/lib/python3.9/site-packages/wikibaseintegrator/wbi_helpers.py", line 127, in mediawiki_api_call
    raise ModificationFailed(json_data['error'])
wikibaseintegrator.wbi_exceptions.ModificationFailed: '[[Item:Q349|Q349]] not found'
2023-07-14 20:30:52,482:ERROR:ModificationFailed error encountered: '[[Item:Q349|Q349]] not found'
2023-07-14 20:30:54,699:ERROR:KeyError encountered: 'Proposal 306'
2023-07-14 20:30:55,285:ERROR:KeyError encountered: 'Proposal 305'
2023-07-14 20:30:55,286:ERROR:KeyError encountered: 'Proposal 307'
2023-07-14 20:31:01,697:ERROR:Error while writing to the Wikibase instance
Traceback (most recent call last):
  File "/home/lubianat/Documents/base_venv/lib/python3.9/site-packages/wikibaseintegrator/entities/baseentity.py", line 244, in _write
    json_result: dict = edit_entity(data=data, id=entity_id, type=self.type, summary=summary, clear=clear, is_bot=is_bot, allow_anonymous=allow_anonymous,
  File "/home/lubianat/Documents/base_venv/lib/python3.9/site-packages/wikibaseintegrator/wbi_helpers.py", line 335, in edit_entity
    return mediawiki_api_call_helper(data=params, is_bot=is_bot, **kwargs)
  File "/home/lubianat/Documents/base_venv/lib/python3.9/site-packages/wikibaseintegrator/wbi_helpers.py", line 217, in mediawiki_api_call_helper
    return mediawiki_api_call('POST', mediawiki_api_url=mediawiki_api_url, session=session, data=data, headers=headers, max_retries=max_retries, retry_after=retry_after, **kwargs)
  File "/home/lubianat/Documents/base_venv/lib/python3.9/site-packages/wikibaseintegrator/wbi_helpers.py", line 127, in mediawiki_api_call
    raise ModificationFailed(json_data['error'])
wikibaseintegrator.wbi_exceptions.ModificationFailed: '[[Item:Q334|Q334]] not found'
2023-07-14 20:31:01,697:ERROR:ModificationFailed error encountered: '[[Item:Q334|Q334]] not found'
2023-07-14 20:31:01,698:ERROR:KeyError encountered: 'Proposal 307'
2023-07-14 20:31:05,074:ERROR:Error while writing to the Wikibase instance
Traceback (most recent call last):
  File "/home/lubianat/Documents/base_venv/lib/python3.9/site-packages/wikibaseintegrator/entities/baseentity.py", line 244, in _write
    json_result: dict = edit_entity(data=data, id=entity_id, type=self.type, summary=summary, clear=clear, is_bot=is_bot, allow_anonymous=allow_anonymous,
  File "/home/lubianat/Documents/base_venv/lib/python3.9/site-packages/wikibaseintegrator/wbi_helpers.py", line 335, in edit_entity
    return mediawiki_api_call_helper(data=params, is_bot=is_bot, **kwargs)
  File "/home/lubianat/Documents/base_venv/lib/python3.9/site-packages/wikibaseintegrator/wbi_helpers.py", line 217, in mediawiki_api_call_helper
    return mediawiki_api_call('POST', mediawiki_api_url=mediawiki_api_url, session=session, data=data, headers=headers, max_retries=max_retries, retry_after=retry_after, **kwargs)
  File "/home/lubianat/Documents/base_venv/lib/python3.9/site-packages/wikibaseintegrator/wbi_helpers.py", line 127, in mediawiki_api_call
    raise ModificationFailed(json_data['error'])
wikibaseintegrator.wbi_exceptions.ModificationFailed: '[[Item:Q349|Q349]] not found'
2023-07-14 20:31:05,075:ERROR:ModificationFailed error encountered: '[[Item:Q349|Q349]] not found'
2023-07-14 20:31:06,098:ERROR:Error while writing to the Wikibase instance
Traceback (most recent call last):
  File "/home/lubianat/Documents/base_venv/lib/python3.9/site-packages/wikibaseintegrator/entities/baseentity.py", line 244, in _write
    json_result: dict = edit_entity(data=data, id=entity_id, type=self.type, summary=summary, clear=clear, is_bot=is_bot, allow_anonymous=allow_anonymous,
  File "/home/lubianat/Documents/base_venv/lib/python3.9/site-packages/wikibaseintegrator/wbi_helpers.py", line 335, in edit_entity
    return mediawiki_api_call_helper(data=params, is_bot=is_bot, **kwargs)
  File "/home/lubianat/Documents/base_venv/lib/python3.9/site-packages/wikibaseintegrator/wbi_helpers.py", line 217, in mediawiki_api_call_helper
    return mediawiki_api_call('POST', mediawiki_api_url=mediawiki_api_url, session=session, data=data, headers=headers, max_retries=max_retries, retry_after=retry_after, **kwargs)
  File "/home/lubianat/Documents/base_venv/lib/python3.9/site-packages/wikibaseintegrator/wbi_helpers.py", line 127, in mediawiki_api_call
    raise ModificationFailed(json_data['error'])
wikibaseintegrator.wbi_exceptions.ModificationFailed: '[[Item:Q334|Q334]] not found'
2023-07-14 20:31:06,099:ERROR:ModificationFailed error encountered: '[[Item:Q334|Q334]] not found'
2023-07-14 20:31:06,101:ERROR:KeyError encountered: 'Proposal 306'
2023-07-14 20:31:08,484:ERROR:KeyError encountered: 'Proposal 313'
2023-07-14 20:31:12,775:ERROR:Error while writing to the Wikibase instance
Traceback (most recent call last):
  File "/home/lubianat/Documents/base_venv/lib/python3.9/site-packages/wikibaseintegrator/entities/baseentity.py", line 244, in _write
    json_result: dict = edit_entity(data=data, id=entity_id, type=self.type, summary=summary, clear=clear, is_bot=is_bot, allow_anonymous=allow_anonymous,
  File "/home/lubianat/Documents/base_venv/lib/python3.9/site-packages/wikibaseintegrator/wbi_helpers.py", line 335, in edit_entity
    return mediawiki_api_call_helper(data=params, is_bot=is_bot, **kwargs)
  File "/home/lubianat/Documents/base_venv/lib/python3.9/site-packages/wikibaseintegrator/wbi_helpers.py", line 217, in mediawiki_api_call_helper
    return mediawiki_api_call('POST', mediawiki_api_url=mediawiki_api_url, session=session, data=data, headers=headers, max_retries=max_retries, retry_after=retry_after, **kwargs)
  File "/home/lubianat/Documents/base_venv/lib/python3.9/site-packages/wikibaseintegrator/wbi_helpers.py", line 127, in mediawiki_api_call
    raise ModificationFailed(json_data['error'])
wikibaseintegrator.wbi_exceptions.ModificationFailed: '[[Item:Q334|Q334]] not found'
2023-07-14 20:31:12,776:ERROR:ModificationFailed error encountered: '[[Item:Q334|Q334]] not found'
2023-07-14 20:31:16,183:ERROR:KeyError encountered: 'Proposal 303'
2023-07-14 20:54:35,745:ERROR:KeyError encountered: 'Proposal 303'
2023-07-14 20:54:35,746:ERROR:KeyError encountered: 'Proposal 303'
2023-07-14 20:54:35,747:ERROR:KeyError encountered: 'Proposal 304'
2023-07-14 20:54:35,748:ERROR:KeyError encountered: 'Proposal 306'
2023-07-14 20:54:35,749:ERROR:KeyError encountered: 'Proposal 306'
2023-07-14 20:54:35,750:ERROR:KeyError encountered: 'Proposal 306'
2023-07-14 20:54:35,752:ERROR:KeyError encountered: 'Proposal 306'
2023-07-14 20:54:35,753:ERROR:KeyError encountered: 'Proposal 306'
2023-07-14 20:54:35,754:ERROR:KeyError encountered: 'Proposal 306'
2023-07-14 20:54:35,755:ERROR:KeyError encountered: 'Proposal 308'
2023-07-14 20:54:35,756:ERROR:KeyError encountered: 'Proposal 311'
2023-07-14 20:54:35,757:ERROR:KeyError encountered: 'Proposal 311'
2023-07-14 20:54:35,758:ERROR:KeyError encountered: 'Proposal 316'
2023-07-14 20:54:35,759:ERROR:KeyError encountered: 'Proposal 316'
2023-07-14 20:54:35,760:ERROR:KeyError encountered: 'Proposal 316'
2023-07-14 20:54:35,761:ERROR:KeyError encountered: 'Proposal 316'
2023-07-14 20:54:35,762:ERROR:KeyError encountered: 'Proposal 316'
2023-07-14 20:54:35,762:ERROR:KeyError encountered: 'Proposal 316'
2023-07-14 20:54:35,763:ERROR:KeyError encountered: 'Proposal 317'
2023-07-14 20:54:35,764:ERROR:KeyError encountered: 'Proposal 317'
2023-07-14 20:54:35,764:ERROR:KeyError encountered: 'Proposal 318'
2023-07-14 20:54:35,765:ERROR:KeyError encountered: 'Proposal 319'
2023-07-14 21:08:43,093:ERROR:KeyError encountered: 'Proposal 307'
2023-07-14 21:18:54,414:ERROR:KeyError encountered: 'Proposal 315'
2023-07-14 21:18:54,415:ERROR:KeyError encountered: 'Proposal 313'
2023-07-14 21:18:54,415:ERROR:KeyError encountered: 'Proposal 316'
2023-07-14 21:18:55,233:ERROR:KeyError encountered: 'Proposal 315'
2023-07-14 21:18:55,233:ERROR:KeyError encountered: 'Proposal 306'
2023-07-14 21:18:55,234:ERROR:KeyError encountered: 'Proposal 303'
2023-07-14 21:18:55,857:ERROR:KeyError encountered: 'Proposal 316'
2023-07-14 21:18:56,943:ERROR:KeyError encountered: 'Proposal 316'
2023-07-14 21:18:56,943:ERROR:KeyError encountered: 'Proposal 305'
2023-07-14 21:18:56,944:ERROR:KeyError encountered: 'Proposal 307'
2023-07-14 21:18:59,767:ERROR:KeyError encountered: 'Proposal 306'
2023-07-14 21:19:00,349:ERROR:KeyError encountered: 'Proposal 305'
2023-07-14 21:19:00,350:ERROR:KeyError encountered: 'Proposal 307'
2023-07-14 21:19:02,085:ERROR:KeyError encountered: 'Proposal 307'
2023-07-14 21:19:02,877:ERROR:KeyError encountered: 'Proposal 306'
2023-07-14 21:19:03,775:ERROR:KeyError encountered: 'Proposal 313'
2023-07-14 21:19:06,252:ERROR:KeyError encountered: 'Proposal 303'
2023-07-14 21:23:35,309:ERROR:KeyError encountered: 'Proposal 307'
2023-07-14 21:23:35,309:ERROR:KeyError encountered: 'Proposal 315'
2023-07-14 21:23:35,310:ERROR:KeyError encountered: 'Proposal 313'
2023-07-14 21:23:35,310:ERROR:KeyError encountered: 'Proposal 316'
2023-07-14 21:23:40,388:ERROR:KeyError encountered: 'Proposal 306'
2023-07-14 21:23:40,388:ERROR:KeyError encountered: 'Proposal 303'
2023-07-14 21:23:52,162:ERROR:KeyError encountered: 'Proposal 305'
2023-07-14 21:23:55,439:ERROR:Error while writing to the Wikibase instance
Traceback (most recent call last):
  File "/home/lubianat/Documents/base_venv/lib/python3.9/site-packages/wikibaseintegrator/entities/baseentity.py", line 244, in _write
    json_result: dict = edit_entity(data=data, id=entity_id, type=self.type, summary=summary, clear=clear, is_bot=is_bot, allow_anonymous=allow_anonymous,
  File "/home/lubianat/Documents/base_venv/lib/python3.9/site-packages/wikibaseintegrator/wbi_helpers.py", line 335, in edit_entity
    return mediawiki_api_call_helper(data=params, is_bot=is_bot, **kwargs)
  File "/home/lubianat/Documents/base_venv/lib/python3.9/site-packages/wikibaseintegrator/wbi_helpers.py", line 217, in mediawiki_api_call_helper
    return mediawiki_api_call('POST', mediawiki_api_url=mediawiki_api_url, session=session, data=data, headers=headers, max_retries=max_retries, retry_after=retry_after, **kwargs)
  File "/home/lubianat/Documents/base_venv/lib/python3.9/site-packages/wikibaseintegrator/wbi_helpers.py", line 127, in mediawiki_api_call
    raise ModificationFailed(json_data['error'])
wikibaseintegrator.wbi_exceptions.ModificationFailed: '[[Item:Q349|Q349]] not found'
2023-07-14 21:23:55,440:ERROR:ModificationFailed error encountered: '[[Item:Q349|Q349]] not found'
2023-07-14 21:24:03,307:ERROR:Error while writing to the Wikibase instance
Traceback (most recent call last):
  File "/home/lubianat/Documents/base_venv/lib/python3.9/site-packages/wikibaseintegrator/entities/baseentity.py", line 244, in _write
    json_result: dict = edit_entity(data=data, id=entity_id, type=self.type, summary=summary, clear=clear, is_bot=is_bot, allow_anonymous=allow_anonymous,
  File "/home/lubianat/Documents/base_venv/lib/python3.9/site-packages/wikibaseintegrator/wbi_helpers.py", line 335, in edit_entity
    return mediawiki_api_call_helper(data=params, is_bot=is_bot, **kwargs)
  File "/home/lubianat/Documents/base_venv/lib/python3.9/site-packages/wikibaseintegrator/wbi_helpers.py", line 217, in mediawiki_api_call_helper
    return mediawiki_api_call('POST', mediawiki_api_url=mediawiki_api_url, session=session, data=data, headers=headers, max_retries=max_retries, retry_after=retry_after, **kwargs)
  File "/home/lubianat/Documents/base_venv/lib/python3.9/site-packages/wikibaseintegrator/wbi_helpers.py", line 127, in mediawiki_api_call
    raise ModificationFailed(json_data['error'])
wikibaseintegrator.wbi_exceptions.ModificationFailed: '[[Item:Q334|Q334]] not found'
2023-07-14 21:24:03,307:ERROR:ModificationFailed error encountered: '[[Item:Q334|Q334]] not found'
2023-07-14 21:28:33,858:ERROR:Error while writing to the Wikibase instance
Traceback (most recent call last):
  File "/home/lubianat/Documents/base_venv/lib/python3.9/site-packages/wikibaseintegrator/entities/baseentity.py", line 244, in _write
    json_result: dict = edit_entity(data=data, id=entity_id, type=self.type, summary=summary, clear=clear, is_bot=is_bot, allow_anonymous=allow_anonymous,
  File "/home/lubianat/Documents/base_venv/lib/python3.9/site-packages/wikibaseintegrator/wbi_helpers.py", line 335, in edit_entity
    return mediawiki_api_call_helper(data=params, is_bot=is_bot, **kwargs)
  File "/home/lubianat/Documents/base_venv/lib/python3.9/site-packages/wikibaseintegrator/wbi_helpers.py", line 217, in mediawiki_api_call_helper
    return mediawiki_api_call('POST', mediawiki_api_url=mediawiki_api_url, session=session, data=data, headers=headers, max_retries=max_retries, retry_after=retry_after, **kwargs)
  File "/home/lubianat/Documents/base_venv/lib/python3.9/site-packages/wikibaseintegrator/wbi_helpers.py", line 127, in mediawiki_api_call
    raise ModificationFailed(json_data['error'])
wikibaseintegrator.wbi_exceptions.ModificationFailed: '[[Item:Q349|Q349]] not found'
2023-07-14 21:28:33,859:ERROR:ModificationFailed error encountered: '[[Item:Q349|Q349]] not found'
2023-07-14 21:29:41,237:ERROR:Error while writing to the Wikibase instance
Traceback (most recent call last):
  File "/home/lubianat/Documents/base_venv/lib/python3.9/site-packages/wikibaseintegrator/entities/baseentity.py", line 244, in _write
    json_result: dict = edit_entity(data=data, id=entity_id, type=self.type, summary=summary, clear=clear, is_bot=is_bot, allow_anonymous=allow_anonymous,
  File "/home/lubianat/Documents/base_venv/lib/python3.9/site-packages/wikibaseintegrator/wbi_helpers.py", line 335, in edit_entity
    return mediawiki_api_call_helper(data=params, is_bot=is_bot, **kwargs)
  File "/home/lubianat/Documents/base_venv/lib/python3.9/site-packages/wikibaseintegrator/wbi_helpers.py", line 217, in mediawiki_api_call_helper
    return mediawiki_api_call('POST', mediawiki_api_url=mediawiki_api_url, session=session, data=data, headers=headers, max_retries=max_retries, retry_after=retry_after, **kwargs)
  File "/home/lubianat/Documents/base_venv/lib/python3.9/site-packages/wikibaseintegrator/wbi_helpers.py", line 127, in mediawiki_api_call
    raise ModificationFailed(json_data['error'])
wikibaseintegrator.wbi_exceptions.ModificationFailed: '[[Item:Q348|Q348]] not found'
2023-07-14 21:29:41,238:ERROR:ModificationFailed error encountered: '[[Item:Q348|Q348]] not found'
2023-07-14 21:29:55,269:ERROR:KeyError encountered: 'Proposal 304'
2023-07-14 21:29:55,269:ERROR:KeyError encountered: 'Proposal 308'
2023-07-14 21:29:55,270:ERROR:KeyError encountered: 'Proposal 311'
2023-07-14 21:29:55,270:ERROR:KeyError encountered: 'Proposal 317'
2023-07-14 21:29:55,270:ERROR:KeyError encountered: 'Proposal 318'
2023-07-14 21:29:55,271:ERROR:KeyError encountered: 'Proposal 319'
2023-07-14 23:04:53,695:ERROR:Error while writing to the Wikibase instance
Traceback (most recent call last):
  File "/home/lubianat/Documents/base_venv/lib/python3.9/site-packages/wikibaseintegrator/entities/baseentity.py", line 244, in _write
    json_result: dict = edit_entity(data=data, id=entity_id, type=self.type, summary=summary, clear=clear, is_bot=is_bot, allow_anonymous=allow_anonymous,
  File "/home/lubianat/Documents/base_venv/lib/python3.9/site-packages/wikibaseintegrator/wbi_helpers.py", line 335, in edit_entity
    return mediawiki_api_call_helper(data=params, is_bot=is_bot, **kwargs)
  File "/home/lubianat/Documents/base_venv/lib/python3.9/site-packages/wikibaseintegrator/wbi_helpers.py", line 190, in mediawiki_api_call_helper
    data.update({'token': login.get_edit_token()})
  File "/home/lubianat/Documents/base_venv/lib/python3.9/site-packages/wikibaseintegrator/wbi_login.py", line 92, in get_edit_token
    self.generate_edit_credentials()
  File "/home/lubianat/Documents/base_venv/lib/python3.9/site-packages/wikibaseintegrator/wbi_login.py", line 68, in generate_edit_credentials
    raise LoginError("Login failed. An anonymous token was returned.")
wikibaseintegrator.wbi_login.LoginError: Login failed. An anonymous token was returned.
