2023-07-17 10:38:03,648:ERROR:Error while writing to the Wikibase instance
Traceback (most recent call last):
  File "/home/lubianat/Documents/base_venv/lib/python3.9/site-packages/wikibaseintegrator/entities/baseentity.py", line 244, in _write
    json_result: dict = edit_entity(data=data, id=entity_id, type=self.type, summary=summary, clear=clear, is_bot=is_bot, allow_anonymous=allow_anonymous,
  File "/home/lubianat/Documents/base_venv/lib/python3.9/site-packages/wikibaseintegrator/wbi_helpers.py", line 335, in edit_entity
    return mediawiki_api_call_helper(data=params, is_bot=is_bot, **kwargs)
  File "/home/lubianat/Documents/base_venv/lib/python3.9/site-packages/wikibaseintegrator/wbi_helpers.py", line 217, in mediawiki_api_call_helper
    return mediawiki_api_call('POST', mediawiki_api_url=mediawiki_api_url, session=session, data=data, headers=headers, max_retries=max_retries, retry_after=retry_after, **kwargs)
  File "/home/lubianat/Documents/base_venv/lib/python3.9/site-packages/wikibaseintegrator/wbi_helpers.py", line 127, in mediawiki_api_call
    raise ModificationFailed(json_data['error'])
wikibaseintegrator.wbi_exceptions.ModificationFailed: '[[Item:Q349|Q349]] not found'
2023-07-17 10:38:03,649:ERROR:Failed to write item: '[[Item:Q349|Q349]] not found'
2023-07-17 10:40:55,072:ERROR:Error while writing to the Wikibase instance
Traceback (most recent call last):
  File "/home/lubianat/Documents/base_venv/lib/python3.9/site-packages/wikibaseintegrator/entities/baseentity.py", line 244, in _write
    json_result: dict = edit_entity(data=data, id=entity_id, type=self.type, summary=summary, clear=clear, is_bot=is_bot, allow_anonymous=allow_anonymous,
  File "/home/lubianat/Documents/base_venv/lib/python3.9/site-packages/wikibaseintegrator/wbi_helpers.py", line 335, in edit_entity
    return mediawiki_api_call_helper(data=params, is_bot=is_bot, **kwargs)
  File "/home/lubianat/Documents/base_venv/lib/python3.9/site-packages/wikibaseintegrator/wbi_helpers.py", line 217, in mediawiki_api_call_helper
    return mediawiki_api_call('POST', mediawiki_api_url=mediawiki_api_url, session=session, data=data, headers=headers, max_retries=max_retries, retry_after=retry_after, **kwargs)
  File "/home/lubianat/Documents/base_venv/lib/python3.9/site-packages/wikibaseintegrator/wbi_helpers.py", line 127, in mediawiki_api_call
    raise ModificationFailed(json_data['error'])
wikibaseintegrator.wbi_exceptions.ModificationFailed: '[[Item:Q349|Q349]] not found'
2023-07-17 10:40:55,073:ERROR:Failed to write item: '[[Item:Q349|Q349]] not found'
2023-07-17 10:41:54,773:ERROR:Error while writing to the Wikibase instance
Traceback (most recent call last):
  File "/home/lubianat/Documents/base_venv/lib/python3.9/site-packages/wikibaseintegrator/entities/baseentity.py", line 244, in _write
    json_result: dict = edit_entity(data=data, id=entity_id, type=self.type, summary=summary, clear=clear, is_bot=is_bot, allow_anonymous=allow_anonymous,
  File "/home/lubianat/Documents/base_venv/lib/python3.9/site-packages/wikibaseintegrator/wbi_helpers.py", line 335, in edit_entity
    return mediawiki_api_call_helper(data=params, is_bot=is_bot, **kwargs)
  File "/home/lubianat/Documents/base_venv/lib/python3.9/site-packages/wikibaseintegrator/wbi_helpers.py", line 217, in mediawiki_api_call_helper
    return mediawiki_api_call('POST', mediawiki_api_url=mediawiki_api_url, session=session, data=data, headers=headers, max_retries=max_retries, retry_after=retry_after, **kwargs)
  File "/home/lubianat/Documents/base_venv/lib/python3.9/site-packages/wikibaseintegrator/wbi_helpers.py", line 127, in mediawiki_api_call
    raise ModificationFailed(json_data['error'])
wikibaseintegrator.wbi_exceptions.ModificationFailed: '[[Item:Q349|Q349]] not found'
2023-07-17 10:41:54,773:ERROR:Failed to write item: '[[Item:Q349|Q349]] not found'
2023-07-17 10:42:04,808:ERROR:Error while writing to the Wikibase instance
Traceback (most recent call last):
  File "/home/lubianat/Documents/base_venv/lib/python3.9/site-packages/wikibaseintegrator/entities/baseentity.py", line 244, in _write
    json_result: dict = edit_entity(data=data, id=entity_id, type=self.type, summary=summary, clear=clear, is_bot=is_bot, allow_anonymous=allow_anonymous,
  File "/home/lubianat/Documents/base_venv/lib/python3.9/site-packages/wikibaseintegrator/wbi_helpers.py", line 335, in edit_entity
    return mediawiki_api_call_helper(data=params, is_bot=is_bot, **kwargs)
  File "/home/lubianat/Documents/base_venv/lib/python3.9/site-packages/wikibaseintegrator/wbi_helpers.py", line 217, in mediawiki_api_call_helper
    return mediawiki_api_call('POST', mediawiki_api_url=mediawiki_api_url, session=session, data=data, headers=headers, max_retries=max_retries, retry_after=retry_after, **kwargs)
  File "/home/lubianat/Documents/base_venv/lib/python3.9/site-packages/wikibaseintegrator/wbi_helpers.py", line 127, in mediawiki_api_call
    raise ModificationFailed(json_data['error'])
wikibaseintegrator.wbi_exceptions.ModificationFailed: '[[Item:Q349|Q349]] not found'
2023-07-17 10:42:04,809:ERROR:Failed to write item: '[[Item:Q349|Q349]] not found'
2023-07-17 10:42:14,035:ERROR:Error while writing to the Wikibase instance
Traceback (most recent call last):
  File "/home/lubianat/Documents/base_venv/lib/python3.9/site-packages/wikibaseintegrator/entities/baseentity.py", line 244, in _write
    json_result: dict = edit_entity(data=data, id=entity_id, type=self.type, summary=summary, clear=clear, is_bot=is_bot, allow_anonymous=allow_anonymous,
  File "/home/lubianat/Documents/base_venv/lib/python3.9/site-packages/wikibaseintegrator/wbi_helpers.py", line 335, in edit_entity
    return mediawiki_api_call_helper(data=params, is_bot=is_bot, **kwargs)
  File "/home/lubianat/Documents/base_venv/lib/python3.9/site-packages/wikibaseintegrator/wbi_helpers.py", line 217, in mediawiki_api_call_helper
    return mediawiki_api_call('POST', mediawiki_api_url=mediawiki_api_url, session=session, data=data, headers=headers, max_retries=max_retries, retry_after=retry_after, **kwargs)
  File "/home/lubianat/Documents/base_venv/lib/python3.9/site-packages/wikibaseintegrator/wbi_helpers.py", line 127, in mediawiki_api_call
    raise ModificationFailed(json_data['error'])
wikibaseintegrator.wbi_exceptions.ModificationFailed: '[[Item:Q351|Q351]] not found'
2023-07-17 10:42:14,036:ERROR:Failed to write item: '[[Item:Q351|Q351]] not found'
2023-07-17 10:42:15,253:ERROR:Error while writing to the Wikibase instance
Traceback (most recent call last):
  File "/home/lubianat/Documents/base_venv/lib/python3.9/site-packages/wikibaseintegrator/entities/baseentity.py", line 244, in _write
    json_result: dict = edit_entity(data=data, id=entity_id, type=self.type, summary=summary, clear=clear, is_bot=is_bot, allow_anonymous=allow_anonymous,
  File "/home/lubianat/Documents/base_venv/lib/python3.9/site-packages/wikibaseintegrator/wbi_helpers.py", line 335, in edit_entity
    return mediawiki_api_call_helper(data=params, is_bot=is_bot, **kwargs)
  File "/home/lubianat/Documents/base_venv/lib/python3.9/site-packages/wikibaseintegrator/wbi_helpers.py", line 217, in mediawiki_api_call_helper
    return mediawiki_api_call('POST', mediawiki_api_url=mediawiki_api_url, session=session, data=data, headers=headers, max_retries=max_retries, retry_after=retry_after, **kwargs)
  File "/home/lubianat/Documents/base_venv/lib/python3.9/site-packages/wikibaseintegrator/wbi_helpers.py", line 127, in mediawiki_api_call
    raise ModificationFailed(json_data['error'])
wikibaseintegrator.wbi_exceptions.ModificationFailed: '[[Item:Q334|Q334]] not found'
2023-07-17 10:42:15,254:ERROR:Failed to write item: '[[Item:Q334|Q334]] not found'
2023-07-17 10:42:18,121:ERROR:Error while writing to the Wikibase instance
Traceback (most recent call last):
  File "/home/lubianat/Documents/base_venv/lib/python3.9/site-packages/wikibaseintegrator/entities/baseentity.py", line 244, in _write
    json_result: dict = edit_entity(data=data, id=entity_id, type=self.type, summary=summary, clear=clear, is_bot=is_bot, allow_anonymous=allow_anonymous,
  File "/home/lubianat/Documents/base_venv/lib/python3.9/site-packages/wikibaseintegrator/wbi_helpers.py", line 335, in edit_entity
    return mediawiki_api_call_helper(data=params, is_bot=is_bot, **kwargs)
  File "/home/lubianat/Documents/base_venv/lib/python3.9/site-packages/wikibaseintegrator/wbi_helpers.py", line 217, in mediawiki_api_call_helper
    return mediawiki_api_call('POST', mediawiki_api_url=mediawiki_api_url, session=session, data=data, headers=headers, max_retries=max_retries, retry_after=retry_after, **kwargs)
  File "/home/lubianat/Documents/base_venv/lib/python3.9/site-packages/wikibaseintegrator/wbi_helpers.py", line 127, in mediawiki_api_call
    raise ModificationFailed(json_data['error'])
wikibaseintegrator.wbi_exceptions.ModificationFailed: '[[Item:Q346|Q346]] not found'
2023-07-17 10:42:18,122:ERROR:Failed to write item: '[[Item:Q346|Q346]] not found'
2023-07-17 10:42:19,350:ERROR:Error while writing to the Wikibase instance
Traceback (most recent call last):
  File "/home/lubianat/Documents/base_venv/lib/python3.9/site-packages/wikibaseintegrator/entities/baseentity.py", line 244, in _write
    json_result: dict = edit_entity(data=data, id=entity_id, type=self.type, summary=summary, clear=clear, is_bot=is_bot, allow_anonymous=allow_anonymous,
  File "/home/lubianat/Documents/base_venv/lib/python3.9/site-packages/wikibaseintegrator/wbi_helpers.py", line 335, in edit_entity
    return mediawiki_api_call_helper(data=params, is_bot=is_bot, **kwargs)
  File "/home/lubianat/Documents/base_venv/lib/python3.9/site-packages/wikibaseintegrator/wbi_helpers.py", line 217, in mediawiki_api_call_helper
    return mediawiki_api_call('POST', mediawiki_api_url=mediawiki_api_url, session=session, data=data, headers=headers, max_retries=max_retries, retry_after=retry_after, **kwargs)
  File "/home/lubianat/Documents/base_venv/lib/python3.9/site-packages/wikibaseintegrator/wbi_helpers.py", line 127, in mediawiki_api_call
    raise ModificationFailed(json_data['error'])
wikibaseintegrator.wbi_exceptions.ModificationFailed: '[[Item:Q346|Q346]] not found'
2023-07-17 10:42:19,351:ERROR:Failed to write item: '[[Item:Q346|Q346]] not found'
2023-07-17 10:45:31,427:ERROR:Error while writing to the Wikibase instance
Traceback (most recent call last):
  File "/home/lubianat/Documents/base_venv/lib/python3.9/site-packages/wikibaseintegrator/entities/baseentity.py", line 244, in _write
    json_result: dict = edit_entity(data=data, id=entity_id, type=self.type, summary=summary, clear=clear, is_bot=is_bot, allow_anonymous=allow_anonymous,
  File "/home/lubianat/Documents/base_venv/lib/python3.9/site-packages/wikibaseintegrator/wbi_helpers.py", line 335, in edit_entity
    return mediawiki_api_call_helper(data=params, is_bot=is_bot, **kwargs)
  File "/home/lubianat/Documents/base_venv/lib/python3.9/site-packages/wikibaseintegrator/wbi_helpers.py", line 217, in mediawiki_api_call_helper
    return mediawiki_api_call('POST', mediawiki_api_url=mediawiki_api_url, session=session, data=data, headers=headers, max_retries=max_retries, retry_after=retry_after, **kwargs)
  File "/home/lubianat/Documents/base_venv/lib/python3.9/site-packages/wikibaseintegrator/wbi_helpers.py", line 127, in mediawiki_api_call
    raise ModificationFailed(json_data['error'])
wikibaseintegrator.wbi_exceptions.ModificationFailed: 'Malformed input: Although the idea of the game show seems fun, I just don’t see a fit for nouns.\u2028 We won’t have a dedicated video ready in time, leaving us with nothing more than a game with noggles floating in space. So people won’t get an idea about nouns in any case. I don’t see nouns promoting our nounish-ness as a commercialised video add where the only thing we do is promoting a prize pool we have nothing to do with. It does not fit us. If we want to reach an audience via pure adds I would suggest making a full page in the NYT or some other newspaper/magazine.'
2023-07-17 10:45:31,428:ERROR:Failed to write item: 'Malformed input: Although the idea of the game show seems fun, I just don’t see a fit for nouns.\u2028 We won’t have a dedicated video ready in time, leaving us with nothing more than a game with noggles floating in space. So people won’t get an idea about nouns in any case. I don’t see nouns promoting our nounish-ness as a commercialised video add where the only thing we do is promoting a prize pool we have nothing to do with. It does not fit us. If we want to reach an audience via pure adds I would suggest making a full page in the NYT or some other newspaper/magazine.'
2023-07-17 10:45:43,543:ERROR:Error while writing to the Wikibase instance
Traceback (most recent call last):
  File "/home/lubianat/Documents/base_venv/lib/python3.9/site-packages/wikibaseintegrator/entities/baseentity.py", line 244, in _write
    json_result: dict = edit_entity(data=data, id=entity_id, type=self.type, summary=summary, clear=clear, is_bot=is_bot, allow_anonymous=allow_anonymous,
  File "/home/lubianat/Documents/base_venv/lib/python3.9/site-packages/wikibaseintegrator/wbi_helpers.py", line 335, in edit_entity
    return mediawiki_api_call_helper(data=params, is_bot=is_bot, **kwargs)
  File "/home/lubianat/Documents/base_venv/lib/python3.9/site-packages/wikibaseintegrator/wbi_helpers.py", line 217, in mediawiki_api_call_helper
    return mediawiki_api_call('POST', mediawiki_api_url=mediawiki_api_url, session=session, data=data, headers=headers, max_retries=max_retries, retry_after=retry_after, **kwargs)
  File "/home/lubianat/Documents/base_venv/lib/python3.9/site-packages/wikibaseintegrator/wbi_helpers.py", line 127, in mediawiki_api_call
    raise ModificationFailed(json_data['error'])
wikibaseintegrator.wbi_exceptions.ModificationFailed: 'Malformed input: Keep up the good work CDT!\u2028 ---------------------------- Good morning @Will!\u2028 ----------------------\u2028 I don’t think it’s a good idea to have censored my Discord post about Poap.eth’s 10 million dollar ‘never going to be accepted’ cryptopunk bid. It was a blatant and cheesy attempt at self-promotion to the punk community. This is historically relevant to understand that these actions are not in isolation.\u2028\u2028 Why is it okay to throw guys like Machi (another Nouner) under the bus publicly (who BTW rightfully deserves the criticism) but not a guy who has so many instances of manipulative tactics who many believe is a detriment to the project. How many screenshots of comments with their own words (anti-Nounder, anti-veto, delegation blackmail, etc) need to be posted in order for the Nouns ecosystem to realize this? Anyhow, I’m done with ranting about this topic. As they say, “you make the bed you lie in.”'
2023-07-17 10:45:43,543:ERROR:Failed to write item: 'Malformed input: Keep up the good work CDT!\u2028 ---------------------------- Good morning @Will!\u2028 ----------------------\u2028 I don’t think it’s a good idea to have censored my Discord post about Poap.eth’s 10 million dollar ‘never going to be accepted’ cryptopunk bid. It was a blatant and cheesy attempt at self-promotion to the punk community. This is historically relevant to understand that these actions are not in isolation.\u2028\u2028 Why is it okay to throw guys like Machi (another Nouner) under the bus publicly (who BTW rightfully deserves the criticism) but not a guy who has so many instances of manipulative tactics who many believe is a detriment to the project. How many screenshots of comments with their own words (anti-Nounder, anti-veto, delegation blackmail, etc) need to be posted in order for the Nouns ecosystem to realize this? Anyhow, I’m done with ranting about this topic. As they say, “you make the bed you lie in.”'
2023-07-17 10:46:00,439:ERROR:Error while writing to the Wikibase instance
Traceback (most recent call last):
  File "/home/lubianat/Documents/base_venv/lib/python3.9/site-packages/wikibaseintegrator/entities/baseentity.py", line 244, in _write
    json_result: dict = edit_entity(data=data, id=entity_id, type=self.type, summary=summary, clear=clear, is_bot=is_bot, allow_anonymous=allow_anonymous,
  File "/home/lubianat/Documents/base_venv/lib/python3.9/site-packages/wikibaseintegrator/wbi_helpers.py", line 335, in edit_entity
    return mediawiki_api_call_helper(data=params, is_bot=is_bot, **kwargs)
  File "/home/lubianat/Documents/base_venv/lib/python3.9/site-packages/wikibaseintegrator/wbi_helpers.py", line 217, in mediawiki_api_call_helper
    return mediawiki_api_call('POST', mediawiki_api_url=mediawiki_api_url, session=session, data=data, headers=headers, max_retries=max_retries, retry_after=retry_after, **kwargs)
  File "/home/lubianat/Documents/base_venv/lib/python3.9/site-packages/wikibaseintegrator/wbi_helpers.py", line 127, in mediawiki_api_call
    raise ModificationFailed(json_data['error'])
wikibaseintegrator.wbi_exceptions.ModificationFailed: '[[Item:Q349|Q349]] not found'
2023-07-17 10:46:00,439:ERROR:Failed to write item: '[[Item:Q349|Q349]] not found'
2023-07-17 10:46:38,327:ERROR:Error while writing to the Wikibase instance
Traceback (most recent call last):
  File "/home/lubianat/Documents/base_venv/lib/python3.9/site-packages/wikibaseintegrator/entities/baseentity.py", line 244, in _write
    json_result: dict = edit_entity(data=data, id=entity_id, type=self.type, summary=summary, clear=clear, is_bot=is_bot, allow_anonymous=allow_anonymous,
  File "/home/lubianat/Documents/base_venv/lib/python3.9/site-packages/wikibaseintegrator/wbi_helpers.py", line 335, in edit_entity
    return mediawiki_api_call_helper(data=params, is_bot=is_bot, **kwargs)
  File "/home/lubianat/Documents/base_venv/lib/python3.9/site-packages/wikibaseintegrator/wbi_helpers.py", line 217, in mediawiki_api_call_helper
    return mediawiki_api_call('POST', mediawiki_api_url=mediawiki_api_url, session=session, data=data, headers=headers, max_retries=max_retries, retry_after=retry_after, **kwargs)
  File "/home/lubianat/Documents/base_venv/lib/python3.9/site-packages/wikibaseintegrator/wbi_helpers.py", line 127, in mediawiki_api_call
    raise ModificationFailed(json_data['error'])
wikibaseintegrator.wbi_exceptions.ModificationFailed: '[[Item:Q349|Q349]] not found'
2023-07-17 10:46:38,327:ERROR:Failed to write item: '[[Item:Q349|Q349]] not found'
2023-07-17 10:46:59,832:ERROR:Error while writing to the Wikibase instance
Traceback (most recent call last):
  File "/home/lubianat/Documents/base_venv/lib/python3.9/site-packages/wikibaseintegrator/entities/baseentity.py", line 244, in _write
    json_result: dict = edit_entity(data=data, id=entity_id, type=self.type, summary=summary, clear=clear, is_bot=is_bot, allow_anonymous=allow_anonymous,
  File "/home/lubianat/Documents/base_venv/lib/python3.9/site-packages/wikibaseintegrator/wbi_helpers.py", line 335, in edit_entity
    return mediawiki_api_call_helper(data=params, is_bot=is_bot, **kwargs)
  File "/home/lubianat/Documents/base_venv/lib/python3.9/site-packages/wikibaseintegrator/wbi_helpers.py", line 217, in mediawiki_api_call_helper
    return mediawiki_api_call('POST', mediawiki_api_url=mediawiki_api_url, session=session, data=data, headers=headers, max_retries=max_retries, retry_after=retry_after, **kwargs)
  File "/home/lubianat/Documents/base_venv/lib/python3.9/site-packages/wikibaseintegrator/wbi_helpers.py", line 127, in mediawiki_api_call
    raise ModificationFailed(json_data['error'])
wikibaseintegrator.wbi_exceptions.ModificationFailed: '[[Item:Q349|Q349]] not found'
2023-07-17 10:46:59,833:ERROR:Failed to write item: '[[Item:Q349|Q349]] not found'
2023-07-17 10:47:03,213:ERROR:Error while writing to the Wikibase instance
Traceback (most recent call last):
  File "/home/lubianat/Documents/base_venv/lib/python3.9/site-packages/wikibaseintegrator/entities/baseentity.py", line 244, in _write
    json_result: dict = edit_entity(data=data, id=entity_id, type=self.type, summary=summary, clear=clear, is_bot=is_bot, allow_anonymous=allow_anonymous,
  File "/home/lubianat/Documents/base_venv/lib/python3.9/site-packages/wikibaseintegrator/wbi_helpers.py", line 335, in edit_entity
    return mediawiki_api_call_helper(data=params, is_bot=is_bot, **kwargs)
  File "/home/lubianat/Documents/base_venv/lib/python3.9/site-packages/wikibaseintegrator/wbi_helpers.py", line 217, in mediawiki_api_call_helper
    return mediawiki_api_call('POST', mediawiki_api_url=mediawiki_api_url, session=session, data=data, headers=headers, max_retries=max_retries, retry_after=retry_after, **kwargs)
  File "/home/lubianat/Documents/base_venv/lib/python3.9/site-packages/wikibaseintegrator/wbi_helpers.py", line 127, in mediawiki_api_call
    raise ModificationFailed(json_data['error'])
wikibaseintegrator.wbi_exceptions.ModificationFailed: '[[Item:Q348|Q348]] not found'
2023-07-17 10:47:03,213:ERROR:Failed to write item: '[[Item:Q348|Q348]] not found'
2023-07-17 10:47:07,718:ERROR:Error while writing to the Wikibase instance
Traceback (most recent call last):
  File "/home/lubianat/Documents/base_venv/lib/python3.9/site-packages/wikibaseintegrator/entities/baseentity.py", line 244, in _write
    json_result: dict = edit_entity(data=data, id=entity_id, type=self.type, summary=summary, clear=clear, is_bot=is_bot, allow_anonymous=allow_anonymous,
  File "/home/lubianat/Documents/base_venv/lib/python3.9/site-packages/wikibaseintegrator/wbi_helpers.py", line 335, in edit_entity
    return mediawiki_api_call_helper(data=params, is_bot=is_bot, **kwargs)
  File "/home/lubianat/Documents/base_venv/lib/python3.9/site-packages/wikibaseintegrator/wbi_helpers.py", line 217, in mediawiki_api_call_helper
    return mediawiki_api_call('POST', mediawiki_api_url=mediawiki_api_url, session=session, data=data, headers=headers, max_retries=max_retries, retry_after=retry_after, **kwargs)
  File "/home/lubianat/Documents/base_venv/lib/python3.9/site-packages/wikibaseintegrator/wbi_helpers.py", line 127, in mediawiki_api_call
    raise ModificationFailed(json_data['error'])
wikibaseintegrator.wbi_exceptions.ModificationFailed: '[[Item:Q351|Q351]] not found'
2023-07-17 10:47:07,718:ERROR:Failed to write item: '[[Item:Q351|Q351]] not found'
2023-07-17 10:47:09,355:ERROR:Error while writing to the Wikibase instance
Traceback (most recent call last):
  File "/home/lubianat/Documents/base_venv/lib/python3.9/site-packages/wikibaseintegrator/entities/baseentity.py", line 244, in _write
    json_result: dict = edit_entity(data=data, id=entity_id, type=self.type, summary=summary, clear=clear, is_bot=is_bot, allow_anonymous=allow_anonymous,
  File "/home/lubianat/Documents/base_venv/lib/python3.9/site-packages/wikibaseintegrator/wbi_helpers.py", line 335, in edit_entity
    return mediawiki_api_call_helper(data=params, is_bot=is_bot, **kwargs)
  File "/home/lubianat/Documents/base_venv/lib/python3.9/site-packages/wikibaseintegrator/wbi_helpers.py", line 217, in mediawiki_api_call_helper
    return mediawiki_api_call('POST', mediawiki_api_url=mediawiki_api_url, session=session, data=data, headers=headers, max_retries=max_retries, retry_after=retry_after, **kwargs)
  File "/home/lubianat/Documents/base_venv/lib/python3.9/site-packages/wikibaseintegrator/wbi_helpers.py", line 127, in mediawiki_api_call
    raise ModificationFailed(json_data['error'])
wikibaseintegrator.wbi_exceptions.ModificationFailed: '[[Item:Q334|Q334]] not found'
2023-07-17 10:47:09,355:ERROR:Failed to write item: '[[Item:Q334|Q334]] not found'
2023-07-17 10:47:36,493:ERROR:Error while writing to the Wikibase instance
Traceback (most recent call last):
  File "/home/lubianat/Documents/base_venv/lib/python3.9/site-packages/wikibaseintegrator/entities/baseentity.py", line 244, in _write
    json_result: dict = edit_entity(data=data, id=entity_id, type=self.type, summary=summary, clear=clear, is_bot=is_bot, allow_anonymous=allow_anonymous,
  File "/home/lubianat/Documents/base_venv/lib/python3.9/site-packages/wikibaseintegrator/wbi_helpers.py", line 335, in edit_entity
    return mediawiki_api_call_helper(data=params, is_bot=is_bot, **kwargs)
  File "/home/lubianat/Documents/base_venv/lib/python3.9/site-packages/wikibaseintegrator/wbi_helpers.py", line 217, in mediawiki_api_call_helper
    return mediawiki_api_call('POST', mediawiki_api_url=mediawiki_api_url, session=session, data=data, headers=headers, max_retries=max_retries, retry_after=retry_after, **kwargs)
  File "/home/lubianat/Documents/base_venv/lib/python3.9/site-packages/wikibaseintegrator/wbi_helpers.py", line 127, in mediawiki_api_call
    raise ModificationFailed(json_data['error'])
wikibaseintegrator.wbi_exceptions.ModificationFailed: 'Data value corrupt:'
2023-07-17 10:47:36,493:ERROR:Failed to write item: 'Data value corrupt:'
2023-07-17 10:49:24,118:ERROR:Error while writing to the Wikibase instance
Traceback (most recent call last):
  File "/home/lubianat/Documents/base_venv/lib/python3.9/site-packages/wikibaseintegrator/entities/baseentity.py", line 244, in _write
    json_result: dict = edit_entity(data=data, id=entity_id, type=self.type, summary=summary, clear=clear, is_bot=is_bot, allow_anonymous=allow_anonymous,
  File "/home/lubianat/Documents/base_venv/lib/python3.9/site-packages/wikibaseintegrator/wbi_helpers.py", line 335, in edit_entity
    return mediawiki_api_call_helper(data=params, is_bot=is_bot, **kwargs)
  File "/home/lubianat/Documents/base_venv/lib/python3.9/site-packages/wikibaseintegrator/wbi_helpers.py", line 217, in mediawiki_api_call_helper
    return mediawiki_api_call('POST', mediawiki_api_url=mediawiki_api_url, session=session, data=data, headers=headers, max_retries=max_retries, retry_after=retry_after, **kwargs)
  File "/home/lubianat/Documents/base_venv/lib/python3.9/site-packages/wikibaseintegrator/wbi_helpers.py", line 127, in mediawiki_api_call
    raise ModificationFailed(json_data['error'])
wikibaseintegrator.wbi_exceptions.ModificationFailed: '[[Item:Q349|Q349]] not found'
2023-07-17 10:49:24,119:ERROR:Failed to write item: '[[Item:Q349|Q349]] not found'
2023-07-17 10:49:55,659:ERROR:Error while writing to the Wikibase instance
Traceback (most recent call last):
  File "/home/lubianat/Documents/base_venv/lib/python3.9/site-packages/wikibaseintegrator/entities/baseentity.py", line 244, in _write
    json_result: dict = edit_entity(data=data, id=entity_id, type=self.type, summary=summary, clear=clear, is_bot=is_bot, allow_anonymous=allow_anonymous,
  File "/home/lubianat/Documents/base_venv/lib/python3.9/site-packages/wikibaseintegrator/wbi_helpers.py", line 335, in edit_entity
    return mediawiki_api_call_helper(data=params, is_bot=is_bot, **kwargs)
  File "/home/lubianat/Documents/base_venv/lib/python3.9/site-packages/wikibaseintegrator/wbi_helpers.py", line 217, in mediawiki_api_call_helper
    return mediawiki_api_call('POST', mediawiki_api_url=mediawiki_api_url, session=session, data=data, headers=headers, max_retries=max_retries, retry_after=retry_after, **kwargs)
  File "/home/lubianat/Documents/base_venv/lib/python3.9/site-packages/wikibaseintegrator/wbi_helpers.py", line 127, in mediawiki_api_call
    raise ModificationFailed(json_data['error'])
wikibaseintegrator.wbi_exceptions.ModificationFailed: '[[Item:Q349|Q349]] not found'
2023-07-17 10:49:55,660:ERROR:Failed to write item: '[[Item:Q349|Q349]] not found'
2023-07-17 10:50:09,074:ERROR:Error while writing to the Wikibase instance
Traceback (most recent call last):
  File "/home/lubianat/Documents/base_venv/lib/python3.9/site-packages/wikibaseintegrator/entities/baseentity.py", line 244, in _write
    json_result: dict = edit_entity(data=data, id=entity_id, type=self.type, summary=summary, clear=clear, is_bot=is_bot, allow_anonymous=allow_anonymous,
  File "/home/lubianat/Documents/base_venv/lib/python3.9/site-packages/wikibaseintegrator/wbi_helpers.py", line 335, in edit_entity
    return mediawiki_api_call_helper(data=params, is_bot=is_bot, **kwargs)
  File "/home/lubianat/Documents/base_venv/lib/python3.9/site-packages/wikibaseintegrator/wbi_helpers.py", line 217, in mediawiki_api_call_helper
    return mediawiki_api_call('POST', mediawiki_api_url=mediawiki_api_url, session=session, data=data, headers=headers, max_retries=max_retries, retry_after=retry_after, **kwargs)
  File "/home/lubianat/Documents/base_venv/lib/python3.9/site-packages/wikibaseintegrator/wbi_helpers.py", line 127, in mediawiki_api_call
    raise ModificationFailed(json_data['error'])
wikibaseintegrator.wbi_exceptions.ModificationFailed: '[[Item:Q349|Q349]] not found'
2023-07-17 10:50:09,074:ERROR:Failed to write item: '[[Item:Q349|Q349]] not found'
2023-07-17 10:50:12,658:ERROR:Error while writing to the Wikibase instance
Traceback (most recent call last):
  File "/home/lubianat/Documents/base_venv/lib/python3.9/site-packages/wikibaseintegrator/entities/baseentity.py", line 244, in _write
    json_result: dict = edit_entity(data=data, id=entity_id, type=self.type, summary=summary, clear=clear, is_bot=is_bot, allow_anonymous=allow_anonymous,
  File "/home/lubianat/Documents/base_venv/lib/python3.9/site-packages/wikibaseintegrator/wbi_helpers.py", line 335, in edit_entity
    return mediawiki_api_call_helper(data=params, is_bot=is_bot, **kwargs)
  File "/home/lubianat/Documents/base_venv/lib/python3.9/site-packages/wikibaseintegrator/wbi_helpers.py", line 217, in mediawiki_api_call_helper
    return mediawiki_api_call('POST', mediawiki_api_url=mediawiki_api_url, session=session, data=data, headers=headers, max_retries=max_retries, retry_after=retry_after, **kwargs)
  File "/home/lubianat/Documents/base_venv/lib/python3.9/site-packages/wikibaseintegrator/wbi_helpers.py", line 127, in mediawiki_api_call
    raise ModificationFailed(json_data['error'])
wikibaseintegrator.wbi_exceptions.ModificationFailed: '[[Item:Q349|Q349]] not found'
2023-07-17 10:50:12,658:ERROR:Failed to write item: '[[Item:Q349|Q349]] not found'
2023-07-17 10:50:15,320:ERROR:Error while writing to the Wikibase instance
Traceback (most recent call last):
  File "/home/lubianat/Documents/base_venv/lib/python3.9/site-packages/wikibaseintegrator/entities/baseentity.py", line 244, in _write
    json_result: dict = edit_entity(data=data, id=entity_id, type=self.type, summary=summary, clear=clear, is_bot=is_bot, allow_anonymous=allow_anonymous,
  File "/home/lubianat/Documents/base_venv/lib/python3.9/site-packages/wikibaseintegrator/wbi_helpers.py", line 335, in edit_entity
    return mediawiki_api_call_helper(data=params, is_bot=is_bot, **kwargs)
  File "/home/lubianat/Documents/base_venv/lib/python3.9/site-packages/wikibaseintegrator/wbi_helpers.py", line 217, in mediawiki_api_call_helper
    return mediawiki_api_call('POST', mediawiki_api_url=mediawiki_api_url, session=session, data=data, headers=headers, max_retries=max_retries, retry_after=retry_after, **kwargs)
  File "/home/lubianat/Documents/base_venv/lib/python3.9/site-packages/wikibaseintegrator/wbi_helpers.py", line 127, in mediawiki_api_call
    raise ModificationFailed(json_data['error'])
wikibaseintegrator.wbi_exceptions.ModificationFailed: '[[Item:Q351|Q351]] not found'
2023-07-17 10:50:15,321:ERROR:Failed to write item: '[[Item:Q351|Q351]] not found'
2023-07-17 10:50:16,447:ERROR:Error while writing to the Wikibase instance
Traceback (most recent call last):
  File "/home/lubianat/Documents/base_venv/lib/python3.9/site-packages/wikibaseintegrator/entities/baseentity.py", line 244, in _write
    json_result: dict = edit_entity(data=data, id=entity_id, type=self.type, summary=summary, clear=clear, is_bot=is_bot, allow_anonymous=allow_anonymous,
  File "/home/lubianat/Documents/base_venv/lib/python3.9/site-packages/wikibaseintegrator/wbi_helpers.py", line 335, in edit_entity
    return mediawiki_api_call_helper(data=params, is_bot=is_bot, **kwargs)
  File "/home/lubianat/Documents/base_venv/lib/python3.9/site-packages/wikibaseintegrator/wbi_helpers.py", line 217, in mediawiki_api_call_helper
    return mediawiki_api_call('POST', mediawiki_api_url=mediawiki_api_url, session=session, data=data, headers=headers, max_retries=max_retries, retry_after=retry_after, **kwargs)
  File "/home/lubianat/Documents/base_venv/lib/python3.9/site-packages/wikibaseintegrator/wbi_helpers.py", line 127, in mediawiki_api_call
    raise ModificationFailed(json_data['error'])
wikibaseintegrator.wbi_exceptions.ModificationFailed: '[[Item:Q334|Q334]] not found'
2023-07-17 10:50:16,448:ERROR:Failed to write item: '[[Item:Q334|Q334]] not found'
2023-07-17 10:50:17,472:ERROR:Error while writing to the Wikibase instance
Traceback (most recent call last):
  File "/home/lubianat/Documents/base_venv/lib/python3.9/site-packages/wikibaseintegrator/entities/baseentity.py", line 244, in _write
    json_result: dict = edit_entity(data=data, id=entity_id, type=self.type, summary=summary, clear=clear, is_bot=is_bot, allow_anonymous=allow_anonymous,
  File "/home/lubianat/Documents/base_venv/lib/python3.9/site-packages/wikibaseintegrator/wbi_helpers.py", line 335, in edit_entity
    return mediawiki_api_call_helper(data=params, is_bot=is_bot, **kwargs)
  File "/home/lubianat/Documents/base_venv/lib/python3.9/site-packages/wikibaseintegrator/wbi_helpers.py", line 217, in mediawiki_api_call_helper
    return mediawiki_api_call('POST', mediawiki_api_url=mediawiki_api_url, session=session, data=data, headers=headers, max_retries=max_retries, retry_after=retry_after, **kwargs)
  File "/home/lubianat/Documents/base_venv/lib/python3.9/site-packages/wikibaseintegrator/wbi_helpers.py", line 127, in mediawiki_api_call
    raise ModificationFailed(json_data['error'])
wikibaseintegrator.wbi_exceptions.ModificationFailed: '[[Item:Q346|Q346]] not found'
2023-07-17 10:50:17,472:ERROR:Failed to write item: '[[Item:Q346|Q346]] not found'
2023-07-17 10:50:18,392:ERROR:Error while writing to the Wikibase instance
Traceback (most recent call last):
  File "/home/lubianat/Documents/base_venv/lib/python3.9/site-packages/wikibaseintegrator/entities/baseentity.py", line 244, in _write
    json_result: dict = edit_entity(data=data, id=entity_id, type=self.type, summary=summary, clear=clear, is_bot=is_bot, allow_anonymous=allow_anonymous,
  File "/home/lubianat/Documents/base_venv/lib/python3.9/site-packages/wikibaseintegrator/wbi_helpers.py", line 335, in edit_entity
    return mediawiki_api_call_helper(data=params, is_bot=is_bot, **kwargs)
  File "/home/lubianat/Documents/base_venv/lib/python3.9/site-packages/wikibaseintegrator/wbi_helpers.py", line 217, in mediawiki_api_call_helper
    return mediawiki_api_call('POST', mediawiki_api_url=mediawiki_api_url, session=session, data=data, headers=headers, max_retries=max_retries, retry_after=retry_after, **kwargs)
  File "/home/lubianat/Documents/base_venv/lib/python3.9/site-packages/wikibaseintegrator/wbi_helpers.py", line 127, in mediawiki_api_call
    raise ModificationFailed(json_data['error'])
wikibaseintegrator.wbi_exceptions.ModificationFailed: '[[Item:Q346|Q346]] not found'
2023-07-17 10:50:18,393:ERROR:Failed to write item: '[[Item:Q346|Q346]] not found'
2023-07-17 10:51:21,575:ERROR:Error while writing to the Wikibase instance
Traceback (most recent call last):
  File "/home/lubianat/Documents/base_venv/lib/python3.9/site-packages/wikibaseintegrator/entities/baseentity.py", line 244, in _write
    json_result: dict = edit_entity(data=data, id=entity_id, type=self.type, summary=summary, clear=clear, is_bot=is_bot, allow_anonymous=allow_anonymous,
  File "/home/lubianat/Documents/base_venv/lib/python3.9/site-packages/wikibaseintegrator/wbi_helpers.py", line 335, in edit_entity
    return mediawiki_api_call_helper(data=params, is_bot=is_bot, **kwargs)
  File "/home/lubianat/Documents/base_venv/lib/python3.9/site-packages/wikibaseintegrator/wbi_helpers.py", line 217, in mediawiki_api_call_helper
    return mediawiki_api_call('POST', mediawiki_api_url=mediawiki_api_url, session=session, data=data, headers=headers, max_retries=max_retries, retry_after=retry_after, **kwargs)
  File "/home/lubianat/Documents/base_venv/lib/python3.9/site-packages/wikibaseintegrator/wbi_helpers.py", line 127, in mediawiki_api_call
    raise ModificationFailed(json_data['error'])
wikibaseintegrator.wbi_exceptions.ModificationFailed: 'Malformed input: Although the idea of the game show seems fun, I just don’t see a fit for nouns.\u2028 We won’t have a dedicated video ready in time, leaving us with nothing more than a game with noggles floating in space. So people won’t get an idea about nouns in any case. I don’t see nouns promoting our nounish-ness as a commercialised video add where the only thing we do is promoting a prize pool we have nothing to do with. It does not fit us. If we want to reach an audience via pure adds I would suggest making a full page in the NYT or some other newspaper/magazine.'
2023-07-17 10:51:21,576:ERROR:Failed to write item: 'Malformed input: Although the idea of the game show seems fun, I just don’t see a fit for nouns.\u2028 We won’t have a dedicated video ready in time, leaving us with nothing more than a game with noggles floating in space. So people won’t get an idea about nouns in any case. I don’t see nouns promoting our nounish-ness as a commercialised video add where the only thing we do is promoting a prize pool we have nothing to do with. It does not fit us. If we want to reach an audience via pure adds I would suggest making a full page in the NYT or some other newspaper/magazine.'
2023-07-17 10:51:33,589:ERROR:Error while writing to the Wikibase instance
Traceback (most recent call last):
  File "/home/lubianat/Documents/base_venv/lib/python3.9/site-packages/wikibaseintegrator/entities/baseentity.py", line 244, in _write
    json_result: dict = edit_entity(data=data, id=entity_id, type=self.type, summary=summary, clear=clear, is_bot=is_bot, allow_anonymous=allow_anonymous,
  File "/home/lubianat/Documents/base_venv/lib/python3.9/site-packages/wikibaseintegrator/wbi_helpers.py", line 335, in edit_entity
    return mediawiki_api_call_helper(data=params, is_bot=is_bot, **kwargs)
  File "/home/lubianat/Documents/base_venv/lib/python3.9/site-packages/wikibaseintegrator/wbi_helpers.py", line 217, in mediawiki_api_call_helper
    return mediawiki_api_call('POST', mediawiki_api_url=mediawiki_api_url, session=session, data=data, headers=headers, max_retries=max_retries, retry_after=retry_after, **kwargs)
  File "/home/lubianat/Documents/base_venv/lib/python3.9/site-packages/wikibaseintegrator/wbi_helpers.py", line 127, in mediawiki_api_call
    raise ModificationFailed(json_data['error'])
wikibaseintegrator.wbi_exceptions.ModificationFailed: 'Malformed input: Keep up the good work CDT!\u2028 ---------------------------- Good morning @Will!\u2028 ----------------------\u2028 I don’t think it’s a good idea to have censored my Discord post about Poap.eth’s 10 million dollar ‘never going to be accepted’ cryptopunk bid. It was a blatant and cheesy attempt at self-promotion to the punk community. This is historically relevant to understand that these actions are not in isolation.\u2028\u2028 Why is it okay to throw guys like Machi (another Nouner) under the bus publicly (who BTW rightfully deserves the criticism) but not a guy who has so many instances of manipulative tactics who many believe is a detriment to the project. How many screenshots of comments with their own words (anti-Nounder, anti-veto, delegation blackmail, etc) need to be posted in order for the Nouns ecosystem to realize this? Anyhow, I’m done with ranting about this topic. As they say, “you make the bed you lie in.”'
2023-07-17 10:51:33,590:ERROR:Failed to write item: 'Malformed input: Keep up the good work CDT!\u2028 ---------------------------- Good morning @Will!\u2028 ----------------------\u2028 I don’t think it’s a good idea to have censored my Discord post about Poap.eth’s 10 million dollar ‘never going to be accepted’ cryptopunk bid. It was a blatant and cheesy attempt at self-promotion to the punk community. This is historically relevant to understand that these actions are not in isolation.\u2028\u2028 Why is it okay to throw guys like Machi (another Nouner) under the bus publicly (who BTW rightfully deserves the criticism) but not a guy who has so many instances of manipulative tactics who many believe is a detriment to the project. How many screenshots of comments with their own words (anti-Nounder, anti-veto, delegation blackmail, etc) need to be posted in order for the Nouns ecosystem to realize this? Anyhow, I’m done with ranting about this topic. As they say, “you make the bed you lie in.”'
2023-07-17 10:51:48,814:ERROR:Error while writing to the Wikibase instance
Traceback (most recent call last):
  File "/home/lubianat/Documents/base_venv/lib/python3.9/site-packages/wikibaseintegrator/entities/baseentity.py", line 244, in _write
    json_result: dict = edit_entity(data=data, id=entity_id, type=self.type, summary=summary, clear=clear, is_bot=is_bot, allow_anonymous=allow_anonymous,
  File "/home/lubianat/Documents/base_venv/lib/python3.9/site-packages/wikibaseintegrator/wbi_helpers.py", line 335, in edit_entity
    return mediawiki_api_call_helper(data=params, is_bot=is_bot, **kwargs)
  File "/home/lubianat/Documents/base_venv/lib/python3.9/site-packages/wikibaseintegrator/wbi_helpers.py", line 217, in mediawiki_api_call_helper
    return mediawiki_api_call('POST', mediawiki_api_url=mediawiki_api_url, session=session, data=data, headers=headers, max_retries=max_retries, retry_after=retry_after, **kwargs)
  File "/home/lubianat/Documents/base_venv/lib/python3.9/site-packages/wikibaseintegrator/wbi_helpers.py", line 127, in mediawiki_api_call
    raise ModificationFailed(json_data['error'])
wikibaseintegrator.wbi_exceptions.ModificationFailed: '[[Item:Q349|Q349]] not found'
2023-07-17 10:51:48,815:ERROR:Failed to write item: '[[Item:Q349|Q349]] not found'
2023-07-17 10:52:25,065:ERROR:Error while writing to the Wikibase instance
Traceback (most recent call last):
  File "/home/lubianat/Documents/base_venv/lib/python3.9/site-packages/wikibaseintegrator/entities/baseentity.py", line 244, in _write
    json_result: dict = edit_entity(data=data, id=entity_id, type=self.type, summary=summary, clear=clear, is_bot=is_bot, allow_anonymous=allow_anonymous,
  File "/home/lubianat/Documents/base_venv/lib/python3.9/site-packages/wikibaseintegrator/wbi_helpers.py", line 335, in edit_entity
    return mediawiki_api_call_helper(data=params, is_bot=is_bot, **kwargs)
  File "/home/lubianat/Documents/base_venv/lib/python3.9/site-packages/wikibaseintegrator/wbi_helpers.py", line 217, in mediawiki_api_call_helper
    return mediawiki_api_call('POST', mediawiki_api_url=mediawiki_api_url, session=session, data=data, headers=headers, max_retries=max_retries, retry_after=retry_after, **kwargs)
  File "/home/lubianat/Documents/base_venv/lib/python3.9/site-packages/wikibaseintegrator/wbi_helpers.py", line 127, in mediawiki_api_call
    raise ModificationFailed(json_data['error'])
wikibaseintegrator.wbi_exceptions.ModificationFailed: '[[Item:Q349|Q349]] not found'
2023-07-17 10:52:25,066:ERROR:Failed to write item: '[[Item:Q349|Q349]] not found'
2023-07-17 10:52:38,787:ERROR:Error while writing to the Wikibase instance
Traceback (most recent call last):
  File "/home/lubianat/Documents/base_venv/lib/python3.9/site-packages/wikibaseintegrator/entities/baseentity.py", line 244, in _write
    json_result: dict = edit_entity(data=data, id=entity_id, type=self.type, summary=summary, clear=clear, is_bot=is_bot, allow_anonymous=allow_anonymous,
  File "/home/lubianat/Documents/base_venv/lib/python3.9/site-packages/wikibaseintegrator/wbi_helpers.py", line 335, in edit_entity
    return mediawiki_api_call_helper(data=params, is_bot=is_bot, **kwargs)
  File "/home/lubianat/Documents/base_venv/lib/python3.9/site-packages/wikibaseintegrator/wbi_helpers.py", line 217, in mediawiki_api_call_helper
    return mediawiki_api_call('POST', mediawiki_api_url=mediawiki_api_url, session=session, data=data, headers=headers, max_retries=max_retries, retry_after=retry_after, **kwargs)
  File "/home/lubianat/Documents/base_venv/lib/python3.9/site-packages/wikibaseintegrator/wbi_helpers.py", line 127, in mediawiki_api_call
    raise ModificationFailed(json_data['error'])
wikibaseintegrator.wbi_exceptions.ModificationFailed: '[[Item:Q349|Q349]] not found'
2023-07-17 10:52:38,787:ERROR:Failed to write item: '[[Item:Q349|Q349]] not found'
2023-07-17 10:52:42,473:ERROR:Error while writing to the Wikibase instance
Traceback (most recent call last):
  File "/home/lubianat/Documents/base_venv/lib/python3.9/site-packages/wikibaseintegrator/entities/baseentity.py", line 244, in _write
    json_result: dict = edit_entity(data=data, id=entity_id, type=self.type, summary=summary, clear=clear, is_bot=is_bot, allow_anonymous=allow_anonymous,
  File "/home/lubianat/Documents/base_venv/lib/python3.9/site-packages/wikibaseintegrator/wbi_helpers.py", line 335, in edit_entity
    return mediawiki_api_call_helper(data=params, is_bot=is_bot, **kwargs)
  File "/home/lubianat/Documents/base_venv/lib/python3.9/site-packages/wikibaseintegrator/wbi_helpers.py", line 217, in mediawiki_api_call_helper
    return mediawiki_api_call('POST', mediawiki_api_url=mediawiki_api_url, session=session, data=data, headers=headers, max_retries=max_retries, retry_after=retry_after, **kwargs)
  File "/home/lubianat/Documents/base_venv/lib/python3.9/site-packages/wikibaseintegrator/wbi_helpers.py", line 127, in mediawiki_api_call
    raise ModificationFailed(json_data['error'])
wikibaseintegrator.wbi_exceptions.ModificationFailed: '[[Item:Q348|Q348]] not found'
2023-07-17 10:52:42,474:ERROR:Failed to write item: '[[Item:Q348|Q348]] not found'
2023-07-17 10:52:45,642:ERROR:Error while writing to the Wikibase instance
Traceback (most recent call last):
  File "/home/lubianat/Documents/base_venv/lib/python3.9/site-packages/wikibaseintegrator/entities/baseentity.py", line 244, in _write
    json_result: dict = edit_entity(data=data, id=entity_id, type=self.type, summary=summary, clear=clear, is_bot=is_bot, allow_anonymous=allow_anonymous,
  File "/home/lubianat/Documents/base_venv/lib/python3.9/site-packages/wikibaseintegrator/wbi_helpers.py", line 335, in edit_entity
    return mediawiki_api_call_helper(data=params, is_bot=is_bot, **kwargs)
  File "/home/lubianat/Documents/base_venv/lib/python3.9/site-packages/wikibaseintegrator/wbi_helpers.py", line 217, in mediawiki_api_call_helper
    return mediawiki_api_call('POST', mediawiki_api_url=mediawiki_api_url, session=session, data=data, headers=headers, max_retries=max_retries, retry_after=retry_after, **kwargs)
  File "/home/lubianat/Documents/base_venv/lib/python3.9/site-packages/wikibaseintegrator/wbi_helpers.py", line 127, in mediawiki_api_call
    raise ModificationFailed(json_data['error'])
wikibaseintegrator.wbi_exceptions.ModificationFailed: '[[Item:Q351|Q351]] not found'
2023-07-17 10:52:45,643:ERROR:Failed to write item: '[[Item:Q351|Q351]] not found'
2023-07-17 10:52:46,979:ERROR:Error while writing to the Wikibase instance
Traceback (most recent call last):
  File "/home/lubianat/Documents/base_venv/lib/python3.9/site-packages/wikibaseintegrator/entities/baseentity.py", line 244, in _write
    json_result: dict = edit_entity(data=data, id=entity_id, type=self.type, summary=summary, clear=clear, is_bot=is_bot, allow_anonymous=allow_anonymous,
  File "/home/lubianat/Documents/base_venv/lib/python3.9/site-packages/wikibaseintegrator/wbi_helpers.py", line 335, in edit_entity
    return mediawiki_api_call_helper(data=params, is_bot=is_bot, **kwargs)
  File "/home/lubianat/Documents/base_venv/lib/python3.9/site-packages/wikibaseintegrator/wbi_helpers.py", line 217, in mediawiki_api_call_helper
    return mediawiki_api_call('POST', mediawiki_api_url=mediawiki_api_url, session=session, data=data, headers=headers, max_retries=max_retries, retry_after=retry_after, **kwargs)
  File "/home/lubianat/Documents/base_venv/lib/python3.9/site-packages/wikibaseintegrator/wbi_helpers.py", line 127, in mediawiki_api_call
    raise ModificationFailed(json_data['error'])
wikibaseintegrator.wbi_exceptions.ModificationFailed: '[[Item:Q334|Q334]] not found'
2023-07-17 10:52:46,980:ERROR:Failed to write item: '[[Item:Q334|Q334]] not found'
2023-07-17 10:52:55,486:ERROR:Error while writing to the Wikibase instance
Traceback (most recent call last):
  File "/home/lubianat/Documents/base_venv/lib/python3.9/site-packages/wikibaseintegrator/entities/baseentity.py", line 244, in _write
    json_result: dict = edit_entity(data=data, id=entity_id, type=self.type, summary=summary, clear=clear, is_bot=is_bot, allow_anonymous=allow_anonymous,
  File "/home/lubianat/Documents/base_venv/lib/python3.9/site-packages/wikibaseintegrator/wbi_helpers.py", line 335, in edit_entity
    return mediawiki_api_call_helper(data=params, is_bot=is_bot, **kwargs)
  File "/home/lubianat/Documents/base_venv/lib/python3.9/site-packages/wikibaseintegrator/wbi_helpers.py", line 217, in mediawiki_api_call_helper
    return mediawiki_api_call('POST', mediawiki_api_url=mediawiki_api_url, session=session, data=data, headers=headers, max_retries=max_retries, retry_after=retry_after, **kwargs)
  File "/home/lubianat/Documents/base_venv/lib/python3.9/site-packages/wikibaseintegrator/wbi_helpers.py", line 127, in mediawiki_api_call
    raise ModificationFailed(json_data['error'])
wikibaseintegrator.wbi_exceptions.ModificationFailed: 'Data value corrupt:'
2023-07-17 10:52:55,486:ERROR:Failed to write item: 'Data value corrupt:'
2023-07-17 10:53:45,172:INFO:====== update_proposal_channel_mapping =====
2023-07-17 10:54:53,447:ERROR:Error while writing to the Wikibase instance
Traceback (most recent call last):
  File "/home/lubianat/Documents/base_venv/lib/python3.9/site-packages/wikibaseintegrator/entities/baseentity.py", line 244, in _write
    json_result: dict = edit_entity(data=data, id=entity_id, type=self.type, summary=summary, clear=clear, is_bot=is_bot, allow_anonymous=allow_anonymous,
  File "/home/lubianat/Documents/base_venv/lib/python3.9/site-packages/wikibaseintegrator/wbi_helpers.py", line 335, in edit_entity
    return mediawiki_api_call_helper(data=params, is_bot=is_bot, **kwargs)
  File "/home/lubianat/Documents/base_venv/lib/python3.9/site-packages/wikibaseintegrator/wbi_helpers.py", line 217, in mediawiki_api_call_helper
    return mediawiki_api_call('POST', mediawiki_api_url=mediawiki_api_url, session=session, data=data, headers=headers, max_retries=max_retries, retry_after=retry_after, **kwargs)
  File "/home/lubianat/Documents/base_venv/lib/python3.9/site-packages/wikibaseintegrator/wbi_helpers.py", line 127, in mediawiki_api_call
    raise ModificationFailed(json_data['error'])
wikibaseintegrator.wbi_exceptions.ModificationFailed: '[[Item:Q349|Q349]] not found'
2023-07-17 10:54:53,449:ERROR:ModificationFailed error encountered: '[[Item:Q349|Q349]] not found'
2023-07-17 10:55:05,751:ERROR:Error while writing to the Wikibase instance
Traceback (most recent call last):
  File "/home/lubianat/Documents/base_venv/lib/python3.9/site-packages/wikibaseintegrator/entities/baseentity.py", line 244, in _write
    json_result: dict = edit_entity(data=data, id=entity_id, type=self.type, summary=summary, clear=clear, is_bot=is_bot, allow_anonymous=allow_anonymous,
  File "/home/lubianat/Documents/base_venv/lib/python3.9/site-packages/wikibaseintegrator/wbi_helpers.py", line 335, in edit_entity
    return mediawiki_api_call_helper(data=params, is_bot=is_bot, **kwargs)
  File "/home/lubianat/Documents/base_venv/lib/python3.9/site-packages/wikibaseintegrator/wbi_helpers.py", line 217, in mediawiki_api_call_helper
    return mediawiki_api_call('POST', mediawiki_api_url=mediawiki_api_url, session=session, data=data, headers=headers, max_retries=max_retries, retry_after=retry_after, **kwargs)
  File "/home/lubianat/Documents/base_venv/lib/python3.9/site-packages/wikibaseintegrator/wbi_helpers.py", line 127, in mediawiki_api_call
    raise ModificationFailed(json_data['error'])
wikibaseintegrator.wbi_exceptions.ModificationFailed: '[[Item:Q334|Q334]] not found'
2023-07-17 10:55:05,752:ERROR:ModificationFailed error encountered: '[[Item:Q334|Q334]] not found'
2023-07-17 11:00:42,883:ERROR:Service unavailable (HTTP Code 502). Sleeping for 60 seconds.
2023-07-17 11:02:20,514:ERROR:Error while writing to the Wikibase instance
Traceback (most recent call last):
  File "/home/lubianat/Documents/base_venv/lib/python3.9/site-packages/wikibaseintegrator/entities/baseentity.py", line 244, in _write
    json_result: dict = edit_entity(data=data, id=entity_id, type=self.type, summary=summary, clear=clear, is_bot=is_bot, allow_anonymous=allow_anonymous,
  File "/home/lubianat/Documents/base_venv/lib/python3.9/site-packages/wikibaseintegrator/wbi_helpers.py", line 335, in edit_entity
    return mediawiki_api_call_helper(data=params, is_bot=is_bot, **kwargs)
  File "/home/lubianat/Documents/base_venv/lib/python3.9/site-packages/wikibaseintegrator/wbi_helpers.py", line 217, in mediawiki_api_call_helper
    return mediawiki_api_call('POST', mediawiki_api_url=mediawiki_api_url, session=session, data=data, headers=headers, max_retries=max_retries, retry_after=retry_after, **kwargs)
  File "/home/lubianat/Documents/base_venv/lib/python3.9/site-packages/wikibaseintegrator/wbi_helpers.py", line 127, in mediawiki_api_call
    raise ModificationFailed(json_data['error'])
wikibaseintegrator.wbi_exceptions.ModificationFailed: '[[Item:Q349|Q349]] not found'
2023-07-17 11:02:20,515:ERROR:ModificationFailed error encountered: '[[Item:Q349|Q349]] not found'
2023-07-17 11:03:29,495:ERROR:Error while writing to the Wikibase instance
Traceback (most recent call last):
  File "/home/lubianat/Documents/base_venv/lib/python3.9/site-packages/wikibaseintegrator/entities/baseentity.py", line 244, in _write
    json_result: dict = edit_entity(data=data, id=entity_id, type=self.type, summary=summary, clear=clear, is_bot=is_bot, allow_anonymous=allow_anonymous,
  File "/home/lubianat/Documents/base_venv/lib/python3.9/site-packages/wikibaseintegrator/wbi_helpers.py", line 335, in edit_entity
    return mediawiki_api_call_helper(data=params, is_bot=is_bot, **kwargs)
  File "/home/lubianat/Documents/base_venv/lib/python3.9/site-packages/wikibaseintegrator/wbi_helpers.py", line 217, in mediawiki_api_call_helper
    return mediawiki_api_call('POST', mediawiki_api_url=mediawiki_api_url, session=session, data=data, headers=headers, max_retries=max_retries, retry_after=retry_after, **kwargs)
  File "/home/lubianat/Documents/base_venv/lib/python3.9/site-packages/wikibaseintegrator/wbi_helpers.py", line 127, in mediawiki_api_call
    raise ModificationFailed(json_data['error'])
wikibaseintegrator.wbi_exceptions.ModificationFailed: '[[Item:Q348|Q348]] not found'
2023-07-17 11:03:29,496:ERROR:ModificationFailed error encountered: '[[Item:Q348|Q348]] not found'
2023-07-17 11:06:13,617:INFO:====== update_summaries =====
2023-07-17 11:06:53,066:ERROR:Error while writing to the Wikibase instance
Traceback (most recent call last):
  File "/home/lubianat/Documents/base_venv/lib/python3.9/site-packages/wikibaseintegrator/entities/baseentity.py", line 244, in _write
    json_result: dict = edit_entity(data=data, id=entity_id, type=self.type, summary=summary, clear=clear, is_bot=is_bot, allow_anonymous=allow_anonymous,
  File "/home/lubianat/Documents/base_venv/lib/python3.9/site-packages/wikibaseintegrator/wbi_helpers.py", line 335, in edit_entity
    return mediawiki_api_call_helper(data=params, is_bot=is_bot, **kwargs)
  File "/home/lubianat/Documents/base_venv/lib/python3.9/site-packages/wikibaseintegrator/wbi_helpers.py", line 217, in mediawiki_api_call_helper
    return mediawiki_api_call('POST', mediawiki_api_url=mediawiki_api_url, session=session, data=data, headers=headers, max_retries=max_retries, retry_after=retry_after, **kwargs)
  File "/home/lubianat/Documents/base_venv/lib/python3.9/site-packages/wikibaseintegrator/wbi_helpers.py", line 127, in mediawiki_api_call
    raise ModificationFailed(json_data['error'])
wikibaseintegrator.wbi_exceptions.ModificationFailed: '[[Item:Q349|Q349]] not found'
2023-07-17 11:06:53,067:ERROR:ModificationFailed error encountered: '[[Item:Q349|Q349]] not found'
2023-07-17 11:07:08,700:ERROR:Error while writing to the Wikibase instance
Traceback (most recent call last):
  File "/home/lubianat/Documents/base_venv/lib/python3.9/site-packages/wikibaseintegrator/entities/baseentity.py", line 244, in _write
    json_result: dict = edit_entity(data=data, id=entity_id, type=self.type, summary=summary, clear=clear, is_bot=is_bot, allow_anonymous=allow_anonymous,
  File "/home/lubianat/Documents/base_venv/lib/python3.9/site-packages/wikibaseintegrator/wbi_helpers.py", line 335, in edit_entity
    return mediawiki_api_call_helper(data=params, is_bot=is_bot, **kwargs)
  File "/home/lubianat/Documents/base_venv/lib/python3.9/site-packages/wikibaseintegrator/wbi_helpers.py", line 217, in mediawiki_api_call_helper
    return mediawiki_api_call('POST', mediawiki_api_url=mediawiki_api_url, session=session, data=data, headers=headers, max_retries=max_retries, retry_after=retry_after, **kwargs)
  File "/home/lubianat/Documents/base_venv/lib/python3.9/site-packages/wikibaseintegrator/wbi_helpers.py", line 127, in mediawiki_api_call
    raise ModificationFailed(json_data['error'])
wikibaseintegrator.wbi_exceptions.ModificationFailed: '[[Item:Q334|Q334]] not found'
2023-07-17 11:07:08,700:ERROR:ModificationFailed error encountered: '[[Item:Q334|Q334]] not found'
2023-07-17 11:07:12,438:ERROR:Error while writing to the Wikibase instance
Traceback (most recent call last):
  File "/home/lubianat/Documents/base_venv/lib/python3.9/site-packages/wikibaseintegrator/entities/baseentity.py", line 244, in _write
    json_result: dict = edit_entity(data=data, id=entity_id, type=self.type, summary=summary, clear=clear, is_bot=is_bot, allow_anonymous=allow_anonymous,
  File "/home/lubianat/Documents/base_venv/lib/python3.9/site-packages/wikibaseintegrator/wbi_helpers.py", line 335, in edit_entity
    return mediawiki_api_call_helper(data=params, is_bot=is_bot, **kwargs)
  File "/home/lubianat/Documents/base_venv/lib/python3.9/site-packages/wikibaseintegrator/wbi_helpers.py", line 217, in mediawiki_api_call_helper
    return mediawiki_api_call('POST', mediawiki_api_url=mediawiki_api_url, session=session, data=data, headers=headers, max_retries=max_retries, retry_after=retry_after, **kwargs)
  File "/home/lubianat/Documents/base_venv/lib/python3.9/site-packages/wikibaseintegrator/wbi_helpers.py", line 127, in mediawiki_api_call
    raise ModificationFailed(json_data['error'])
wikibaseintegrator.wbi_exceptions.ModificationFailed: '[[Item:Q349|Q349]] not found'
2023-07-17 11:07:12,439:ERROR:ModificationFailed error encountered: '[[Item:Q349|Q349]] not found'
2023-07-17 11:07:13,475:ERROR:Error while writing to the Wikibase instance
Traceback (most recent call last):
  File "/home/lubianat/Documents/base_venv/lib/python3.9/site-packages/wikibaseintegrator/entities/baseentity.py", line 244, in _write
    json_result: dict = edit_entity(data=data, id=entity_id, type=self.type, summary=summary, clear=clear, is_bot=is_bot, allow_anonymous=allow_anonymous,
  File "/home/lubianat/Documents/base_venv/lib/python3.9/site-packages/wikibaseintegrator/wbi_helpers.py", line 335, in edit_entity
    return mediawiki_api_call_helper(data=params, is_bot=is_bot, **kwargs)
  File "/home/lubianat/Documents/base_venv/lib/python3.9/site-packages/wikibaseintegrator/wbi_helpers.py", line 217, in mediawiki_api_call_helper
    return mediawiki_api_call('POST', mediawiki_api_url=mediawiki_api_url, session=session, data=data, headers=headers, max_retries=max_retries, retry_after=retry_after, **kwargs)
  File "/home/lubianat/Documents/base_venv/lib/python3.9/site-packages/wikibaseintegrator/wbi_helpers.py", line 127, in mediawiki_api_call
    raise ModificationFailed(json_data['error'])
wikibaseintegrator.wbi_exceptions.ModificationFailed: '[[Item:Q334|Q334]] not found'
2023-07-17 11:07:13,475:ERROR:ModificationFailed error encountered: '[[Item:Q334|Q334]] not found'
2023-07-17 11:07:26,345:ERROR:Error while writing to the Wikibase instance
Traceback (most recent call last):
  File "/home/lubianat/Documents/base_venv/lib/python3.9/site-packages/wikibaseintegrator/entities/baseentity.py", line 244, in _write
    json_result: dict = edit_entity(data=data, id=entity_id, type=self.type, summary=summary, clear=clear, is_bot=is_bot, allow_anonymous=allow_anonymous,
  File "/home/lubianat/Documents/base_venv/lib/python3.9/site-packages/wikibaseintegrator/wbi_helpers.py", line 335, in edit_entity
    return mediawiki_api_call_helper(data=params, is_bot=is_bot, **kwargs)
  File "/home/lubianat/Documents/base_venv/lib/python3.9/site-packages/wikibaseintegrator/wbi_helpers.py", line 217, in mediawiki_api_call_helper
    return mediawiki_api_call('POST', mediawiki_api_url=mediawiki_api_url, session=session, data=data, headers=headers, max_retries=max_retries, retry_after=retry_after, **kwargs)
  File "/home/lubianat/Documents/base_venv/lib/python3.9/site-packages/wikibaseintegrator/wbi_helpers.py", line 127, in mediawiki_api_call
    raise ModificationFailed(json_data['error'])
wikibaseintegrator.wbi_exceptions.ModificationFailed: '[[Item:Q334|Q334]] not found'
2023-07-17 11:07:26,345:ERROR:ModificationFailed error encountered: '[[Item:Q334|Q334]] not found'
2023-07-17 11:07:34,813:INFO:====== update_q_and_a =====
2023-07-17 11:14:46,985:ERROR:Error while writing to the Wikibase instance
Traceback (most recent call last):
  File "/home/lubianat/Documents/base_venv/lib/python3.9/site-packages/wikibaseintegrator/entities/baseentity.py", line 244, in _write
    json_result: dict = edit_entity(data=data, id=entity_id, type=self.type, summary=summary, clear=clear, is_bot=is_bot, allow_anonymous=allow_anonymous,
  File "/home/lubianat/Documents/base_venv/lib/python3.9/site-packages/wikibaseintegrator/wbi_helpers.py", line 335, in edit_entity
    return mediawiki_api_call_helper(data=params, is_bot=is_bot, **kwargs)
  File "/home/lubianat/Documents/base_venv/lib/python3.9/site-packages/wikibaseintegrator/wbi_helpers.py", line 217, in mediawiki_api_call_helper
    return mediawiki_api_call('POST', mediawiki_api_url=mediawiki_api_url, session=session, data=data, headers=headers, max_retries=max_retries, retry_after=retry_after, **kwargs)
  File "/home/lubianat/Documents/base_venv/lib/python3.9/site-packages/wikibaseintegrator/wbi_helpers.py", line 127, in mediawiki_api_call
    raise ModificationFailed(json_data['error'])
wikibaseintegrator.wbi_exceptions.ModificationFailed: 'Malformed input: Overall this is great. I’m glad we’re seeing Brian’s more often now. It was an ambitious change and he killed it. It’s a very smart use of real estate and since the Activity rows are clickable it’ll drive traffic to Proposals.--**\u2028\u2028Questions**-- What does “Last seen today” mean?-- What’s the hover color for the buttons, similar blue or reddish? --**\u2028Loved**-- Nav buttons are great, I love the blue for Connect-- “Noun {auctionNum}” to Londrina font is perfect-- I like the cool background-- LOVE the next-minimum-bid being the input-placeholder, perfect- - Would still watch that font size. In mobile input, it seems like a placeholder of a “wider” 3-digit bid like 2xx.69 (vs 1xx.69) may be crowded--**Notes**-- Not crazy about Treasury component being by Home logo. Not used to seeing anything near a top-left logo.- - It’s better on mobile, maybe truly centered though?-- Winning Bid numbers being that big make me wonder about triple digits bids & spacing. I guess, you won’t have the thousandths place decimal so it’ll even out. Maybe still slightly big font? Since it’s the same for winning address try substituting for “beautifulpunks.eth” or “davidzhorvath.eth” or even “marvelvscapcom.eth” to make sure it’ll fit. Those are some of the longer bidders we see.-- Lastly, on mobile, I feel like “Noun {auctionNum}” should be the first thing directly under the Noun, I know it’s a lot to fit in there. Maybe try just flipping arrows/date with “Noun {auctionNum}” just to see--Again, just my $0.02. Really impressed, and again glad you guys are tag-teaming this.'
2023-07-17 11:14:46,986:ERROR:ModificationFailed error encountered: 'Malformed input: Overall this is great. I’m glad we’re seeing Brian’s more often now. It was an ambitious change and he killed it. It’s a very smart use of real estate and since the Activity rows are clickable it’ll drive traffic to Proposals.--**\u2028\u2028Questions**-- What does “Last seen today” mean?-- What’s the hover color for the buttons, similar blue or reddish? --**\u2028Loved**-- Nav buttons are great, I love the blue for Connect-- “Noun {auctionNum}” to Londrina font is perfect-- I like the cool background-- LOVE the next-minimum-bid being the input-placeholder, perfect- - Would still watch that font size. In mobile input, it seems like a placeholder of a “wider” 3-digit bid like 2xx.69 (vs 1xx.69) may be crowded--**Notes**-- Not crazy about Treasury component being by Home logo. Not used to seeing anything near a top-left logo.- - It’s better on mobile, maybe truly centered though?-- Winning Bid numbers being that big make me wonder about triple digits bids & spacing. I guess, you won’t have the thousandths place decimal so it’ll even out. Maybe still slightly big font? Since it’s the same for winning address try substituting for “beautifulpunks.eth” or “davidzhorvath.eth” or even “marvelvscapcom.eth” to make sure it’ll fit. Those are some of the longer bidders we see.-- Lastly, on mobile, I feel like “Noun {auctionNum}” should be the first thing directly under the Noun, I know it’s a lot to fit in there. Maybe try just flipping arrows/date with “Noun {auctionNum}” just to see--Again, just my $0.02. Really impressed, and again glad you guys are tag-teaming this.'
